Workbook

Sheet วิเคราะห์ข้อมูล
A1: ผลรวม ของ จำนวน | C1: เดือน | J1: STOCK | K1: MAX | L1: MIN | M1: AVG | N1: สินค้าที่ต้อง | O1: ยอดขายรายสาขา | S1: STOCK รายสาขา | W1: ความต้องการเพิ่ม | AA1: วันที่ผลิต
A2: รหัสสินค้า | B2: รายละเอียดสินค้า | C2: มกราคม | D2: กุมภาพันธ์ | E2: มีนาคม | F2: เมษายน | G2: พฤษภาคม | H2: มิถุนายน | I2: ผลรวมทั้งหมด | N2: ส่งไปเพิ่ม | O2: 340 | P2: ราชพฤกษ | Q2: บางใหญ่ | R2: บางบอน | S2: 340 | T2: ราชพฤกษ | U2: บางใหญ่ | V2: บางบอน | W2: 340 | X2: ราชพฤกษ | Y2: บางใหญ่ | Z2: บางบอน
A3: ผลรวมทั้งหมด | C3: =SUBTOTAL(9,C4:C1275) -> 3285 | D3: =SUBTOTAL(9,D4:D1275) -> 2868 | E3: =SUBTOTAL(9,E4:E1275) -> 3048 | F3: =SUBTOTAL(9,F4:F1275) -> 3028 | G3: =SUBTOTAL(9,G4:G1275) -> 3019 | H3: =SUBTOTAL(9,H4:H1275) -> 608 | I3: =SUBTOTAL(9,I4:I1275) -> 15856 | J3: =SUBTOTAL(9,J4:J1275) -> 64263 | ... M3: =SUBTOTAL(9,M4:M1275) -> 3049.6 | N3: สำหรับชาย
N4: ทุกสาขา
A5: รหัสสินค้า | B5: รายละเอียดสินค้า
A6: 019-I5-1 | B6: * แร็ค 111 SR-5470 I/S D-MAX ALL NEW 2WD12-on*M14 | C6: =SUMIFS('DATA UPDATE'!$L:$L,'DATA UPDATE'!$E:$E,วิเคราะห์ข้อมูล!A6,'DATA UPDATE'!$B:$B,วิเคราะห์ข้อมูล!$C$2) -> 1 | D6: =SUMIFS('DATA UPDATE'!$L:$L,'DATA UPDATE'!$E:$E,A6,'DATA UPDATE'!$B:$B,$D$2) -> 0 | E6: =SUMIFS('DATA UPDATE'!$L:$L,'DATA UPDATE'!$E:$E,A6,'DATA UPDATE'!$B:$B,$E$2) -> 0 | F6: =SUMIFS('DATA UPDATE'!$L:$L,'DATA UPDATE'!$E:$E,A6,'DATA UPDATE'!$B:$B,$F$2) -> 0 | G6: =SUMIFS('DATA UPDATE'!$L:$L,'DATA UPDATE'!$E:$E,A6,'DATA UPDATE'!$B:$B,$G$2) -> 0 | H6: =SUMIFS('DATA UPDATE'!$L:$L,'DATA UPDATE'!$E:$E,A6,'DATA UPDATE'!$B:$B,$H$2) -> 0 | I6: =SUM(C6:H6) -> 1 | J6: =SUMIFS('UPDATE STOCK'!F:F,'UPDATE STOCK'!A:A,วิเคราะห์ข้อมูล!A6) -> 3 | K6: =MAX(C6:G6) -> 1 | L6: =MIN(C6:G6) -> 0 | M6: =AVERAGE(C6:G6) -> 0.2 | N6: =M6-J6 -> -2.8 | O6: =SUMIFS('DATA UPDATE'!$L:$L,'DATA UPDATE'!$E:$E,วิเคราะห์ข้อมูล!A6,'DATA UPDATE'!$T:$T,วิเคราะห์ข้อมูล!$O$2) -> 1 | P6: =SUMIFS('DATA UPDATE'!$L:$L,'DATA UPDATE'!$E:$E,วิเคราะห์ข้อมูล!A6,'DATA UPDATE'!$T:$T,วิเคราะห์ข้อมูล!$P$2) -> 0 | Q6: =SUMIFS('DATA UPDATE'!$L:$L,'DATA UPDATE'!$E:$E,วิเคราะห์ข้อมูล!A6,'DATA UPDATE'!$T:$T,วิเคราะห์ข้อมูล!$Q$2) -> 0 | R6: =SUMIFS('DATA UPDATE'!$L:$L,'DATA UPDATE'!$D:$D,วิเคราะห์ข้อมูล!A6,'DATA UPDATE'!$T:$T,วิเคราะห์ข้อมูล!$R$2) -> 0 | S6: =SUMIFS('UPDATE STOCK'!$F:$F,'UPDATE STOCK'!$A:$A,A6,'UPDATE STOCK'!$G:$G,$S$2) -> 1 | T6: =SUMIFS('UPDATE STOCK'!$F:$F,'UPDATE STOCK'!$A:$A,A6,'UPDATE STOCK'!$G:$G,$T$2) -> 0 | U6: =SUMIFS('UPDATE STOCK'!$F:$F,'UPDATE STOCK'!$A:$A,วิเคราะห์ข้อมูล!A6,'UPDATE STOCK'!$G:$G,$U$2) -> 2 | V6: =SUMIFS('UPDATE STOCK'!$F:$F,'UPDATE STOCK'!$A:$A,วิเคราะห์ข้อมูล!A6,'UPDATE STOCK'!$G:$G,$V$2) -> 0
A7: 077-T2-114 | B7: * ดิสเบรคหน้า DPX-694 T/A HILUX REVO 2WD (F) | C7: =SUMIFS('DATA UPDATE'!$L:$L,'DATA UPDATE'!$E:$E,วิเคราะห์ข้อมูล!A7,'DATA UPDATE'!$B:$B,วิเคราะห์ข้อมูล!$C$2) -> 0 | D7: =SUMIFS('DATA UPDATE'!$L:$L,'DATA UPDATE'!$E:$E,A7,'DATA UPDATE'!$B:$B,$D$2) -> 5 | E7: =SUMIFS('DATA UPDATE'!$L:$L,'DATA UPDATE'!$E:$E,A7,'DATA UPDATE'!$B:$B,$E$2) -> 1 | F7: =SUMIFS('DATA UPDATE'!$L:$L,'DATA UPDATE'!$E:$E,A7,'DATA UPDATE'!$B:$B,$F$2) -> 0 | G7: =SUMIFS('DATA UPDATE'!$L:$L,'DATA UPDATE'!$E:$E,A7,'DATA UPDATE'!$B:$B,$G$2) -> 0 | H7: =SUMIFS('DATA UPDATE'!$L:$L,'DATA UPDATE'!$E:$E,A7,'DATA UPDATE'!$B:$B,$H$2) -> 0 | I7: =SUM(C7:H7) -> 6 | J7: =SUMIFS('UPDATE STOCK'!F:F,'UPDATE STOCK'!A:A,วิเคราะห์ข้อมูล!A7) -> 12 | K7: =MAX(C7:G7) -> 5 | L7: =MIN(C7:G7) -> 0 | M7: =AVERAGE(C7:G7) -> 1.2 | N7: =M7-J7 -> -10.8 | O7: =SUMIFS('DATA UPDATE'!$L:$L,'DATA UPDATE'!$E:$E,วิเคราะห์ข้อมูล!A7,'DATA UPDATE'!$T:$T,วิเคราะห์ข้อมูล!$O$2) -> 4 | P7: =SUMIFS('DATA UPDATE'!$L:$L,'DATA UPDATE'!$E:$E,วิเคราะห์ข้อมูล!A7,'DATA UPDATE'!$T:$T,วิเคราะห์ข้อมูล!$P$2) -> 0 | Q7: =SUMIFS('DATA UPDATE'!$L:$L,'DATA UPDATE'!$E:$E,วิเคราะห์ข้อมูล!A7,'DATA UPDATE'!$T:$T,วิเคราะห์ข้อมูล!$Q$2) -> 0 | R7: =SUMIFS('DATA UPDATE'!$L:$L,'DATA UPDATE'!$D:$D,วิเคราะห์ข้อมูล!A7,'DATA UPDATE'!$T:$T,วิเคราะห์ข้อมูล!$R$2) -> 0 | S7: =SUMIFS('UPDATE STOCK'!$F:$F,'UPDATE STOCK'!$A:$A,A7,'UPDATE STOCK'!$G:$G,$S$2) -> 5 | T7: =SUMIFS('UPDATE STOCK'!$F:$F,'UPDATE STOCK'!$A:$A,A7,'UPDATE STOCK'!$G:$G,$T$2) -> 0 | U7: =SUMIFS('UPDATE STOCK'!$F:$F,'UPDATE STOCK'!$A:$A,วิเคราะห์ข้อมูล!A7,'UPDATE STOCK'!$G:$G,$U$2) -> 4 | V7: =SUMIFS('UPDATE STOCK'!$F:$F,'UPDATE STOCK'!$A:$A,วิเคราะห์ข้อมูล!A7,'UPDATE STOCK'!$G:$G,$V$2) -> 0
A8: 131-10-23 | B8: *555 SL-3880ลูกหมากกันโคลงT/YVIGO 2 WD(48820-0X010^0K010) | C8: =SUMIFS('DATA UPDATE'!$L:$L,'DATA UPDATE'!$E:$E,วิเคราะห์ข้อมูล!A8,'DATA UPDATE'!$B:$B,วิเคราะห์ข้อมูล!$C$2) -> 0 | D8: =SUMIFS('DATA UPDATE'!$L:$L,'DATA UPDATE'!$E:$E,A8,'DATA UPDATE'!$B:$B,$D$2) -> 0 | E8: =SUMIFS('DATA UPDATE'!$L:$L,'DATA UPDATE'!$E:$E,A8,'DATA UPDATE'!$B:$B,$E$2) -> 0 | F8: =SUMIFS('DATA UPDATE'!$L:$L,'DATA UPDATE'!$E:$E,A8,'DATA UPDATE'!$B:$B,$F$2) -> 0 | G8: =SUMIFS('DATA UPDATE'!$L:$L,'DATA UPDATE'!$E:$E,A8,'DATA UPDATE'!$B:$B,$G$2) -> 2 | H8: =SUMIFS('DATA UPDATE'!$L:$L,'DATA UPDATE'!$E:$E,A8,'DATA UPDATE'!$B:$B,$H$2) -> 0 | I8: =SUM(C8:H8) -> 2 | J8: =SUMIFS('UPDATE STOCK'!F:F,'UPDATE STOCK'!A:A,วิเคราะห์ข้อมูล!A8) -> 6 | K8: =MAX(C8:G8) -> 2 | L8: =MIN(C8:G8) -> 0 | M8: =AVERAGE(C8:G8) -> 0.4 | N8: =M8-J8 -> -5.6 | O8: =SUMIFS('DATA UPDATE'!$L:$L,'DATA UPDATE'!$E:$E,วิเคราะห์ข้อมูล!A8,'DATA UPDATE'!$T:$T,วิเคราะห์ข้อมูล!$O$2) -> 0 | P8: =SUMIFS('DATA UPDATE'!$L:$L,'DATA UPDATE'!$E:$E,วิเคราะห์ข้อมูล!A8,'DATA UPDATE'!$T:$T,วิเคราะห์ข้อมูล!$P$2) -> 0 | Q8: =SUMIFS('DATA UPDATE'!$L:$L,'DATA UPDATE'!$E:$E,วิเคราะห์ข้อมูล!A8,'DATA UPDATE'!$T:$T,วิเคราะห์ข้อมูล!$Q$2) -> 2 | R8: =SUMIFS('DATA UPDATE'!$L:$L,'DATA UPDATE'!$D:$D,วิเคราะห์ข้อมูล!A8,'DATA UPDATE'!$T:$T,วิเคราะห์ข้อมูล!$R$2) -> 0 | S8: =SUMIFS('UPDATE STOCK'!$F:$F,'UPDATE STOCK'!$A:$A,A8,'UPDATE STOCK'!$G:$G,$S$2) -> 4 | T8: =SUMIFS('UPDATE STOCK'!$F:$F,'UPDATE STOCK'!$A:$A,A8,'UPDATE STOCK'!$G:$G,$T$2) -> 2 | U8: =SUMIFS('UPDATE STOCK'!$F:$F,'UPDATE STOCK'!$A:$A,วิเคราะห์ข้อมูล!A8,'UPDATE STOCK'!$G:$G,$U$2) -> 0 | V8: =SUMIFS('UPDATE STOCK'!$F:$F,'UPDATE STOCK'!$A:$A,วิเคราะห์ข้อมูล!A8,'UPDATE STOCK'!$G:$G,$V$2) -> 0
A9: 133-T2-4 | B9: *90916-T2006 สายพานเครื่อง VIGO แท้ (7PK1516 BANDO) | C9: =SUMIFS('DATA UPDATE'!$L:$L,'DATA UPDATE'!$E:$E,วิเคราะห์ข้อมูล!A9,'DATA UPDATE'!$B:$B,วิเคราะห์ข้อมูล!$C$2) -> 1 | D9: =SUMIFS('DATA UPDATE'!$L:$L,'DATA UPDATE'!$E:$E,A9,'DATA UPDATE'!$B:$B,$D$2) -> 0 | E9: =SUMIFS('DATA UPDATE'!$L:$L,'DATA UPDATE'!$E:$E,A9,'DATA UPDATE'!$B:$B,$E$2) -> 1 | F9: =SUMIFS('DATA UPDATE'!$L:$L,'DATA UPDATE'!$E:$E,A9,'DATA UPDATE'!$B:$B,$F$2) -> 0 | G9: =SUMIFS('DATA UPDATE'!$L:$L,'DATA UPDATE'!$E:$E,A9,'DATA UPDATE'!$B:$B,$G$2) -> 1 | H9: =SUMIFS('DATA UPDATE'!$L:$L,'DATA UPDATE'!$E:$E,A9,'DATA UPDATE'!$B:$B,$H$2) -> 0 | I9: =SUM(C9:H9) -> 3 | J9: =SUMIFS('UPDATE STOCK'!F:F,'UPDATE STOCK'!A:A,วิเคราะห์ข้อมูล!A9) -> 3 | K9: =MAX(C9:G9) -> 1 | L9: =MIN(C9:G9) -> 0 | M9: =AVERAGE(C9:G9) -> 0.6 | N9: =M9-J9 -> -2.4 | O9: =SUMIFS('DATA UPDATE'!$L:$L,'DATA UPDATE'!$E:$E,วิเคราะห์ข้อมูล!A9,'DATA UPDATE'!$T:$T,วิเคราะห์ข้อมูล!$O$2) -> 2 | P9: =SUMIFS('DATA UPDATE'!$L:$L,'DATA UPDATE'!$E:$E,วิเคราะห์ข้อมูล!A9,'DATA UPDATE'!$T:$T,วิเคราะห์ข้อมูล!$P$2) -> 0 | Q9: =SUMIFS('DATA UPDATE'!$L:$L,'DATA UPDATE'!$E:$E,วิเคราะห์ข้อมูล!A9,'DATA UPDATE'!$T:$T,วิเคราะห์ข้อมูล!$Q$2) -> 1 | R9: =SUMIFS('DATA UPDATE'!$L:$L,'DATA UPDATE'!$D:$D,วิเคราะห์ข้อมูล!A9,'DATA UPDATE'!$T:$T,วิเคราะห์ข้อมูล!$R$2) -> 0 | S9: =SUMIFS('UPDATE STOCK'!$F:$F,'UPDATE STOCK'!$A:$A,A9,'UPDATE STOCK'!$G:$G,$S$2) -> 2 | T9: =SUMIFS('UPDATE STOCK'!$F:$F,'UPDATE STOCK'!$A:$A,A9,'UPDATE STOCK'!$G:$G,$T$2) -> 0 | U9: =SUMIFS('UPDATE STOCK'!$F:$F,'UPDATE STOCK'!$A:$A,วิเคราะห์ข้อมูล!A9,'UPDATE STOCK'!$G:$G,$U$2) -> 1 | V9: =SUMIFS('UPDATE STOCK'!$F:$F,'UPDATE STOCK'!$A:$A,วิเคราะห์ข้อมูล!A9,'UPDATE STOCK'!$G:$G,$V$2) -> 0
A10: 128-CMF-56638 | B10: *SOLITE แบตแห้ง CMF DIN66L L3 | C10: =SUMIFS('DATA UPDATE'!$L:$L,'DATA UPDATE'!$E:$E,วิเคราะห์ข้อมูล!A10,'DATA UPDATE'!$B:$B,วิเคราะห์ข้อมูล!$C$2) -> 1 | D10: =SUMIFS('DATA UPDATE'!$L:$L,'DATA UPDATE'!$E:$E,A10,'DATA UPDATE'!$B:$B,$D$2) -> 1 | E10: =SUMIFS('DATA UPDATE'!$L:$L,'DATA UPDATE'!$E:$E,A10,'DATA UPDATE'!$B:$B,$E$2) -> 0 | F10: =SUMIFS('DATA UPDATE'!$L:$L,'DATA UPDATE'!$E:$E,A10,'DATA UPDATE'!$B:$B,$F$2) -> 0 | G10: =SUMIFS('DATA UPDATE'!$L:$L,'DATA UPDATE'!$E:$E,A10,'DATA UPDATE'!$B:$B,$G$2) -> 0 | H10: =SUMIFS('DATA UPDATE'!$L:$L,'DATA UPDATE'!$E:$E,A10,'DATA UPDATE'!$B:$B,$H$2) -> 0 | I10: =SUM(C10:H10) -> 2 | J10: =SUMIFS('UPDATE STOCK'!F:F,'UPDATE STOCK'!A:A,วิเคราะห์ข้อมูล!A10) -> 0 | K10: =MAX(C10:G10) -> 1 | L10: =MIN(C10:G10) -> 0 | M10: =AVERAGE(C10:G10) -> 0.4 | N10: =M10-J10 -> 0.4 | O10: =SUMIFS('DATA UPDATE'!$L:$L,'DATA UPDATE'!$E:$E,วิเคราะห์ข้อมูล!A10,'DATA UPDATE'!$T:$T,วิเคราะห์ข้อมูล!$O$2) -> 1 | P10: =SUMIFS('DATA UPDATE'!$L:$L,'DATA UPDATE'!$E:$E,วิเคราะห์ข้อมูล!A10,'DATA UPDATE'!$T:$T,วิเคราะห์ข้อมูล!$P$2) -> 0 | Q10: =SUMIFS('DATA UPDATE'!$L:$L,'DATA UPDATE'!$E:$E,วิเคราะห์ข้อมูล!A10,'DATA UPDATE'!$T:$T,วิเคราะห์ข้อมูล!$Q$2) -> 0 | R10: =SUMIFS('DATA UPDATE'!$L:$L,'DATA UPDATE'!$D:$D,วิเคราะห์ข้อมูล!A10,'DATA UPDATE'!$T:$T,วิเคราะห์ข้อมูล!$R$2) -> 0 | S10: =SUMIFS('UPDATE STOCK'!$F:$F,'UPDATE STOCK'!$A:$A,A10,'UPDATE STOCK'!$G:$G,$S$2) -> 0 | T10: =SUMIFS('UPDATE STOCK'!$F:$F,'UPDATE STOCK'!$A:$A,A10,'UPDATE STOCK'!$G:$G,$T$2) -> 0 | U10: =SUMIFS('UPDATE STOCK'!$F:$F,'UPDATE STOCK'!$A:$A,วิเคราะห์ข้อมูล!A10,'UPDATE STOCK'!$G:$G,$U$2) -> 0 | V10: =SUMIFS('UPDATE STOCK'!$F:$F,'UPDATE STOCK'!$A:$A,วิเคราะห์ข้อมูล!A10,'UPDATE STOCK'!$G:$G,$V$2) -> 0
A11: 128-UMF-56219 | B11: *SOLITE แบตแห้ง Silver DIN65L L2 | C11: =SUMIFS('DATA UPDATE'!$L:$L,'DATA UPDATE'!$E:$E,วิเคราะห์ข้อมูล!A11,'DATA UPDATE'!$B:$B,วิเคราะห์ข้อมูล!$C$2) -> 0 | D11: =SUMIFS('DATA UPDATE'!$L:$L,'DATA UPDATE'!$E:$E,A11,'DATA UPDATE'!$B:$B,$D$2) -> 0 | E11: =SUMIFS('DATA UPDATE'!$L:$L,'DATA UPDATE'!$E:$E,A11,'DATA UPDATE'!$B:$B,$E$2) -> 0 | F11: =SUMIFS('DATA UPDATE'!$L:$L,'DATA UPDATE'!$E:$E,A11,'DATA UPDATE'!$B:$B,$F$2) -> 1 | G11: =SUMIFS('DATA UPDATE'!$L:$L,'DATA UPDATE'!$E:$E,A11,'DATA UPDATE'!$B:$B,$G$2) -> 0 | H11: =SUMIFS('DATA UPDATE'!$L:$L,'DATA UPDATE'!$E:$E,A11,'DATA UPDATE'!$B:$B,$H$2) -> 0 | I11: =SUM(C11:H11) -> 1 | J11: =SUMIFS('UPDATE STOCK'!F:F,'UPDATE STOCK'!A:A,วิเคราะห์ข้อมูล!A11) -> 0 | K11: =MAX(C11:G11) -> 1 | L11: =MIN(C11:G11) -> 0 | M11: =AVERAGE(C11:G11) -> 0.2 | N11: =M11-J11 -> 0.2 | O11: =SUMIFS('DATA UPDATE'!$L:$L,'DATA UPDATE'!$E:$E,วิเคราะห์ข้อมูล!A11,'DATA UPDATE'!$T:$T,วิเคราะห์ข้อมูล!$O$2) -> 0 | P11: =SUMIFS('DATA UPDATE'!$L:$L,'DATA UPDATE'!$E:$E,วิเคราะห์ข้อมูล!A11,'DATA UPDATE'!$T:$T,วิเคราะห์ข้อมูล!$P$2) -> 1 | Q11: =SUMIFS('DATA UPDATE'!$L:$L,'DATA UPDATE'!$E:$E,วิเคราะห์ข้อมูล!A11,'DATA UPDATE'!$T:$T,วิเคราะห์ข้อมูล!$Q$2) -> 0 | R11: =SUMIFS('DATA UPDATE'!$L:$L,'DATA UPDATE'!$D:$D,วิเคราะห์ข้อมูล!A11,'DATA UPDATE'!$T:$T,วิเคราะห์ข้อมูล!$R$2) -> 0 | S11: =SUMIFS('UPDATE STOCK'!$F:$F,'UPDATE STOCK'!$A:$A,A11,'UPDATE STOCK'!$G:$G,$S$2) -> 0 | T11: =SUMIFS('UPDATE STOCK'!$F:$F,'UPDATE STOCK'!$A:$A,A11,'UPDATE STOCK'!$G:$G,$T$2) -> 0 | U11: =SUMIFS('UPDATE STOCK'!$F:$F,'UPDATE STOCK'!$A:$A,วิเคราะห์ข้อมูล!A11,'UPDATE STOCK'!$G:$G,$U$2) -> 0 | V11: =SUMIFS('UPDATE STOCK'!$F:$F,'UPDATE STOCK'!$A:$A,วิเคราะห์ข้อมูล!A11,'UPDATE STOCK'!$G:$G,$V$2) -> 0
A12: 128-GS-LN1 | B12: *แบตเตอรี่ BAGS LN1-DIN55-DURA -55 แอมป์/ชั่วโม ขัวจม | C12: =SUMIFS('DATA UPDATE'!$L:$L,'DATA UPDATE'!$E:$E,วิเคราะห์ข้อมูล!A12,'DATA UPDATE'!$B:$B,วิเคราะห์ข้อมูล!$C$2) -> 0 | D12: =SUMIFS('DATA UPDATE'!$L:$L,'DATA UPDATE'!$E:$E,A12,'DATA UPDATE'!$B:$B,$D$2) -> 0 | E12: =SUMIFS('DATA UPDATE'!$L:$L,'DATA UPDATE'!$E:$E,A12,'DATA UPDATE'!$B:$B,$E$2) -> 0 | F12: =SUMIFS('DATA UPDATE'!$L:$L,'DATA UPDATE'!$E:$E,A12,'DATA UPDATE'!$B:$B,$F$2) -> 0 | G12: =SUMIFS('DATA UPDATE'!$L:$L,'DATA UPDATE'!$E:$E,A12,'DATA UPDATE'!$B:$B,$G$2) -> 1 | H12: =SUMIFS('DATA UPDATE'!$L:$L,'DATA UPDATE'!$E:$E,A12,'DATA UPDATE'!$B:$B,$H$2) -> 0 | I12: =SUM(C12:H12) -> 1 | J12: =SUMIFS('UPDATE STOCK'!F:F,'UPDATE STOCK'!A:A,วิเคราะห์ข้อมูล!A12) -> 5 | K12: =MAX(C12:G12) -> 1 | L12: =MIN(C12:G12) -> 0 | M12: =AVERAGE(C12:G12) -> 0.2 | N12: =M12-J12 -> -4.8 | O12: =SUMIFS('DATA UPDATE'!$L:$L,'DATA UPDATE'!$E:$E,วิเคราะห์ข้อมูล!A12,'DATA UPDATE'!$T:$T,วิเคราะห์ข้อมูล!$O$2) -> 0 | P12: =SUMIFS('DATA UPDATE'!$L:$L,'DATA UPDATE'!$E:$E,วิเคราะห์ข้อมูล!A12,'DATA UPDATE'!$T:$T,วิเคราะห์ข้อมูล!$P$2) -> 1 | Q12: =SUMIFS('DATA UPDATE'!$L:$L,'DATA UPDATE'!$E:$E,วิเคราะห์ข้อมูล!A12,'DATA UPDATE'!$T:$T,วิเคราะห์ข้อมูล!$Q$2) -> 0 | R12: =SUMIFS('DATA UPDATE'!$L:$L,'DATA UPDATE'!$D:$D,วิเคราะห์ข้อมูล!A12,'DATA UPDATE'!$T:$T,วิเคราะห์ข้อมูล!$R$2) -> 0 | S12: =SUMIFS('UPDATE STOCK'!$F:$F,'UPDATE STOCK'!$A:$A,A12,'UPDATE STOCK'!$G:$G,$S$2) -> 0 | T12: =SUMIFS('UPDATE STOCK'!$F:$F,'UPDATE STOCK'!$A:$A,A12,'UPDATE STOCK'!$G:$G,$T$2) -> 1 | U12: =SUMIFS('UPDATE STOCK'!$F:$F,'UPDATE STOCK'!$A:$A,วิเคราะห์ข้อมูล!A12,'UPDATE STOCK'!$G:$G,$U$2) -> 3 | V12: =SUMIFS('UPDATE STOCK'!$F:$F,'UPDATE STOCK'!$A:$A,วิเคราะห์ข้อมูล!A12,'UPDATE STOCK'!$G:$G,$V$2) -> 1
A13: 128-GS-LN3 | B13: *แบตเตอรี่ BAGS LN3-MF-75 แอมป์/ชม. - ขั้วบวกซ้ายใหญ่ | C13: =SUMIFS('DATA UPDATE'!$L:$L,'DATA UPDATE'!$E:$E,วิเคราะห์ข้อมูล!A13,'DATA UPDATE'!$B:$B,วิเคราะห์ข้อมูล!$C$2) -> 0 | D13: =SUMIFS('DATA UPDATE'!$L:$L,'DATA UPDATE'!$E:$E,A13,'DATA UPDATE'!$B:$B,$D$2) -> 2 | E13: =SUMIFS('DATA UPDATE'!$L:$L,'DATA UPDATE'!$E:$E,A13,'DATA UPDATE'!$B:$B,$E$2) -> 0 | F13: =SUMIFS('DATA UPDATE'!$L:$L,'DATA UPDATE'!$E:$E,A13,'DATA UPDATE'!$B:$B,$F$2) -> 1 | G13: =SUMIFS('DATA UPDATE'!$L:$L,'DATA UPDATE'!$E:$E,A13,'DATA UPDATE'!$B:$B,$G$2) -> 2 | H13: =SUMIFS('DATA UPDATE'!$L:$L,'DATA UPDATE'!$E:$E,A13,'DATA UPDATE'!$B:$B,$H$2) -> 1 | I13: =SUM(C13:H13) -> 6 | J13: =SUMIFS('UPDATE STOCK'!F:F,'UPDATE STOCK'!A:A,วิเคราะห์ข้อมูล!A13) -> 3 | K13: =MAX(C13:G13) -> 2 | L13: =MIN(C13:G13) -> 0 | M13: =AVERAGE(C13:G13) -> 1 | N13: =M13-J13 -> -2 | O13: =SUMIFS('DATA UPDATE'!$L:$L,'DATA UPDATE'!$E:$E,วิเคราะห์ข้อมูล!A13,'DATA UPDATE'!$T:$T,วิเคราะห์ข้อมูล!$O$2) -> 4 | P13: =SUMIFS('DATA UPDATE'!$L:$L,'DATA UPDATE'!$E:$E,วิเคราะห์ข้อมูล!A13,'DATA UPDATE'!$T:$T,วิเคราะห์ข้อมูล!$P$2) -> 1 | Q13: =SUMIFS('DATA UPDATE'!$L:$L,'DATA UPDATE'!$E:$E,วิเคราะห์ข้อมูล!A13,'DATA UPDATE'!$T:$T,วิเคราะห์ข้อมูล!$Q$2) -> 0 | R13: =SUMIFS('DATA UPDATE'!$L:$L,'DATA UPDATE'!$D:$D,วิเคราะห์ข้อมูล!A13,'DATA UPDATE'!$T:$T,วิเคราะห์ข้อมูล!$R$2) -> 0 | S13: =SUMIFS('UPDATE STOCK'!$F:$F,'UPDATE STOCK'!$A:$A,A13,'UPDATE STOCK'!$G:$G,$S$2) -> 0 | T13: =SUMIFS('UPDATE STOCK'!$F:$F,'UPDATE STOCK'!$A:$A,A13,'UPDATE STOCK'!$G:$G,$T$2) -> 1 | U13: =SUMIFS('UPDATE STOCK'!$F:$F,'UPDATE STOCK'!$A:$A,วิเคราะห์ข้อมูล!A13,'UPDATE STOCK'!$G:$G,$U$2) -> 1 | V13: =SUMIFS('UPDATE STOCK'!$F:$F,'UPDATE STOCK'!$A:$A,วิเคราะห์ข้อมูล!A13,'UPDATE STOCK'!$G:$G,$V$2) -> 1
A14: 128-GS-LN2 | B14: *แบตเตอรี่ GS BAGS LN2 MF 65แอมป์/ชั่วโมง | C14: =SUMIFS('DATA UPDATE'!$L:$L,'DATA UPDATE'!$E:$E,วิเคราะห์ข้อมูล!A14,'DATA UPDATE'!$B:$B,วิเคราะห์ข้อมูล!$C$2) -> 0 | D14: =SUMIFS('DATA UPDATE'!$L:$L,'DATA UPDATE'!$E:$E,A14,'DATA UPDATE'!$B:$B,$D$2) -> 0 | E14: =SUMIFS('DATA UPDATE'!$L:$L,'DATA UPDATE'!$E:$E,A14,'DATA UPDATE'!$B:$B,$E$2) -> 1 | F14: =SUMIFS('DATA UPDATE'!$L:$L,'DATA UPDATE'!$E:$E,A14,'DATA UPDATE'!$B:$B,$F$2) -> 0 | G14: =SUMIFS('DATA UPDATE'!$L:$L,'DATA UPDATE'!$E:$E,A14,'DATA UPDATE'!$B:$B,$G$2) -> 0 | H14: =SUMIFS('DATA UPDATE'!$L:$L,'DATA UPDATE'!$E:$E,A14,'DATA UPDATE'!$B:$B,$H$2) -> 0 | I14: =SUM(C14:H14) -> 1 | J14: =SUMIFS('UPDATE STOCK'!F:F,'UPDATE STOCK'!A:A,วิเคราะห์ข้อมูล!A14) -> 4 | K14: =MAX(C14:G14) -> 1 | L14: =MIN(C14:G14) -> 0 | M14: =AVERAGE(C14:G14) -> 0.2 | N14: =M14-J14 -> -3.8 | O14: =SUMIFS('DATA UPDATE'!$L:$L,'DATA UPDATE'!$E:$E,วิเคราะห์ข้อมูล!A14,'DATA UPDATE'!$T:$T,วิเคราะห์ข้อมูล!$O$2) -> 0 | P14: =SUMIFS('DATA UPDATE'!$L:$L,'DATA UPDATE'!$E:$E,วิเคราะห์ข้อมูล!A14,'DATA UPDATE'!$T:$T,วิเคราะห์ข้อมูล!$P$2) -> 1 | Q14: =SUMIFS('DATA UPDATE'!$L:$L,'DATA UPDATE'!$E:$E,วิเคราะห์ข้อมูล!A14,'DATA UPDATE'!$T:$T,วิเคราะห์ข้อมูล!$Q$2) -> 0 | R14: =SUMIFS('DATA UPDATE'!$L:$L,'DATA UPDATE'!$D:$D,วิเคราะห์ข้อมูล!A14,'DATA UPDATE'!$T:$T,วิเคราะห์ข้อมูล!$R$2) -> 0 | S14: =SUMIFS('UPDATE STOCK'!$F:$F,'UPDATE STOCK'!$A:$A,A14,'UPDATE STOCK'!$G:$G,$S$2) -> 1 | T14: =SUMIFS('UPDATE STOCK'!$F:$F,'UPDATE STOCK'!$A:$A,A14,'UPDATE STOCK'!$G:$G,$T$2) -> 1 | U14: =SUMIFS('UPDATE STOCK'!$F:$F,'UPDATE STOCK'!$A:$A,วิเคราะห์ข้อมูล!A14,'UPDATE STOCK'!$G:$G,$U$2) -> 1 | V14: =SUMIFS('UPDATE STOCK'!$F:$F,'UPDATE STOCK'!$A:$A,วิเคราะห์ข้อมูล!A14,'UPDATE STOCK'!$G:$G,$V$2) -> 1
A15: 128-GS-MFX90L | B15: *แบตเตอรี่ GS BAGS MFX-90L 75-80 แอมป์/ชั่วโมง | C15: =SUMIFS('DATA UPDATE'!$L:$L,'DATA UPDATE'!$E:$E,วิเคราะห์ข้อมูล!A15,'DATA UPDATE'!$B:$B,วิเคราะห์ข้อมูล!$C$2) -> 2 | D15: =SUMIFS('DATA UPDATE'!$L:$L,'DATA UPDATE'!$E:$E,A15,'DATA UPDATE'!$B:$B,$D$2) -> 2 | E15: =SUMIFS('DATA UPDATE'!$L:$L,'DATA UPDATE'!$E:$E,A15,'DATA UPDATE'!$B:$B,$E$2) -> 1 | F15: =SUMIFS('DATA UPDATE'!$L:$L,'DATA UPDATE'!$E:$E,A15,'DATA UPDATE'!$B:$B,$F$2) -> 3 | G15: =SUMIFS('DATA UPDATE'!$L:$L,'DATA UPDATE'!$E:$E,A15,'DATA UPDATE'!$B:$B,$G$2) -> 0 | H15: =SUMIFS('DATA UPDATE'!$L:$L,'DATA UPDATE'!$E:$E,A15,'DATA UPDATE'!$B:$B,$H$2) -> 0 | I15: =SUM(C15:H15) -> 8 | J15: =SUMIFS('UPDATE STOCK'!F:F,'UPDATE STOCK'!A:A,วิเคราะห์ข้อมูล!A15) -> 2 | K15: =MAX(C15:G15) -> 3 | L15: =MIN(C15:G15) -> 0 | M15: =AVERAGE(C15:G15) -> 1.6 | N15: =M15-J15 -> -0.4 | O15: =SUMIFS('DATA UPDATE'!$L:$L,'DATA UPDATE'!$E:$E,วิเคราะห์ข้อมูล!A15,'DATA UPDATE'!$T:$T,วิเคราะห์ข้อมูล!$O$2) -> 6 | P15: =SUMIFS('DATA UPDATE'!$L:$L,'DATA UPDATE'!$E:$E,วิเคราะห์ข้อมูล!A15,'DATA UPDATE'!$T:$T,วิเคราะห์ข้อมูล!$P$2) -> 1 | Q15: =SUMIFS('DATA UPDATE'!$L:$L,'DATA UPDATE'!$E:$E,วิเคราะห์ข้อมูล!A15,'DATA UPDATE'!$T:$T,วิเคราะห์ข้อมูล!$Q$2) -> 0 | R15: =SUMIFS('DATA UPDATE'!$L:$L,'DATA UPDATE'!$D:$D,วิเคราะห์ข้อมูล!A15,'DATA UPDATE'!$T:$T,วิเคราะห์ข้อมูล!$R$2) -> 0 | S15: =SUMIFS('UPDATE STOCK'!$F:$F,'UPDATE STOCK'!$A:$A,A15,'UPDATE STOCK'!$G:$G,$S$2) -> 0 | T15: =SUMIFS('UPDATE STOCK'!$F:$F,'UPDATE STOCK'!$A:$A,A15,'UPDATE STOCK'!$G:$G,$T$2) -> 0 | U15: =SUMIFS('UPDATE STOCK'!$F:$F,'UPDATE STOCK'!$A:$A,วิเคราะห์ข้อมูล!A15,'UPDATE STOCK'!$G:$G,$U$2) -> 0 | V15: =SUMIFS('UPDATE STOCK'!$F:$F,'UPDATE STOCK'!$A:$A,วิเคราะห์ข้อมูล!A15,'UPDATE STOCK'!$G:$G,$V$2) -> 1
A16: 128-GS-MFX180L | B16: *แบตเตอรี่แห้ง GS BAGS MFX-180L-80แอมป์/ชั่วโมง | C16: =SUMIFS('DATA UPDATE'!$L:$L,'DATA UPDATE'!$E:$E,วิเคราะห์ข้อมูล!A16,'DATA UPDATE'!$B:$B,วิเคราะห์ข้อมูล!$C$2) -> 0 | D16: =SUMIFS('DATA UPDATE'!$L:$L,'DATA UPDATE'!$E:$E,A16,'DATA UPDATE'!$B:$B,$D$2) -> 0 | E16: =SUMIFS('DATA UPDATE'!$L:$L,'DATA UPDATE'!$E:$E,A16,'DATA UPDATE'!$B:$B,$E$2) -> 1 | F16: =SUMIFS('DATA UPDATE'!$L:$L,'DATA UPDATE'!$E:$E,A16,'DATA UPDATE'!$B:$B,$F$2) -> 0 | G16: =SUMIFS('DATA UPDATE'!$L:$L,'DATA UPDATE'!$E:$E,A16,'DATA UPDATE'!$B:$B,$G$2) -> 0 | H16: =SUMIFS('DATA UPDATE'!$L:$L,'DATA UPDATE'!$E:$E,A16,'DATA UPDATE'!$B:$B,$H$2) -> 0 | I16: =SUM(C16:H16) -> 1 | J16: =SUMIFS('UPDATE STOCK'!F:F,'UPDATE STOCK'!A:A,วิเคราะห์ข้อมูล!A16) -> 3 | K16: =MAX(C16:G16) -> 1 | L16: =MIN(C16:G16) -> 0 | M16: =AVERAGE(C16:G16) -> 0.2 | N16: =M16-J16 -> -2.8 | O16: =SUMIFS('DATA UPDATE'!$L:$L,'DATA UPDATE'!$E:$E,วิเคราะห์ข้อมูล!A16,'DATA UPDATE'!$T:$T,วิเคราะห์ข้อมูล!$O$2) -> 0 | P16: =SUMIFS('DATA UPDATE'!$L:$L,'DATA UPDATE'!$E:$E,วิเคราะห์ข้อมูล!A16,'DATA UPDATE'!$T:$T,วิเคราะห์ข้อมูล!$P$2) -> 0 | Q16: =SUMIFS('DATA UPDATE'!$L:$L,'DATA UPDATE'!$E:$E,วิเคราะห์ข้อมูล!A16,'DATA UPDATE'!$T:$T,วิเคราะห์ข้อมูล!$Q$2) -> 0 | R16: =SUMIFS('DATA UPDATE'!$L:$L,'DATA UPDATE'!$D:$D,วิเคราะห์ข้อมูล!A16,'DATA UPDATE'!$T:$T,วิเคราะห์ข้อมูล!$R$2) -> 0 | S16: =SUMIFS('UPDATE STOCK'!$F:$F,'UPDATE STOCK'!$A:$A,A16,'UPDATE STOCK'!$G:$G,$S$2) -> 0 | T16: =SUMIFS('UPDATE STOCK'!$F:$F,'UPDATE STOCK'!$A:$A,A16,'UPDATE STOCK'!$G:$G,$T$2) -> 1 | U16: =SUMIFS('UPDATE STOCK'!$F:$F,'UPDATE STOCK'!$A:$A,วิเคราะห์ข้อมูล!A16,'UPDATE STOCK'!$G:$G,$U$2) -> 0 | V16: =SUMIFS('UPDATE STOCK'!$F:$F,'UPDATE STOCK'!$A:$A,วิเคราะห์ข้อมูล!A16,'UPDATE STOCK'!$G:$G,$V$2) -> 0
A17: 128-GS-MFX50L | B17: *แบตเตอรี่แห้ง GS BAGS MFX-50L 40แอมป์/ชั่วโมง | C17: =SUMIFS('DATA UPDATE'!$L:$L,'DATA UPDATE'!$E:$E,วิเคราะห์ข้อมูล!A17,'DATA UPDATE'!$B:$B,วิเคราะห์ข้อมูล!$C$2) -> 3 | D17: =SUMIFS('DATA UPDATE'!$L:$L,'DATA UPDATE'!$E:$E,A17,'DATA UPDATE'!$B:$B,$D$2) -> 2 | E17: =SUMIFS('DATA UPDATE'!$L:$L,'DATA UPDATE'!$E:$E,A17,'DATA UPDATE'!$B:$B,$E$2) -> 0 | F17: =SUMIFS('DATA UPDATE'!$L:$L,'DATA UPDATE'!$E:$E,A17,'DATA UPDATE'!$B:$B,$F$2) -> 0 | G17: =SUMIFS('DATA UPDATE'!$L:$L,'DATA UPDATE'!$E:$E,A17,'DATA UPDATE'!$B:$B,$G$2) -> 1 | H17: =SUMIFS('DATA UPDATE'!$L:$L,'DATA UPDATE'!$E:$E,A17,'DATA UPDATE'!$B:$B,$H$2) -> 0 | I17: =SUM(C17:H17) -> 6 | J17: =SUMIFS('UPDATE STOCK'!F:F,'UPDATE STOCK'!A:A,วิเคราะห์ข้อมูล!A17) -> 9 | K17: =MAX(C17:G17) -> 3 | L17: =MIN(C17:G17) -> 0 | M17: =AVERAGE(C17:G17) -> 1.2 | N17: =M17-J17 -> -7.8 | O17: =SUMIFS('DATA UPDATE'!$L:$L,'DATA UPDATE'!$E:$E,วิเคราะห์ข้อมูล!A17,'DATA UPDATE'!$T:$T,วิเคราะห์ข้อมูล!$O$2) -> 1 | P17: =SUMIFS('DATA UPDATE'!$L:$L,'DATA UPDATE'!$E:$E,วิเคราะห์ข้อมูล!A17,'DATA UPDATE'!$T:$T,วิเคราะห์ข้อมูล!$P$2) -> 0 | Q17: =SUMIFS('DATA UPDATE'!$L:$L,'DATA UPDATE'!$E:$E,วิเคราะห์ข้อมูล!A17,'DATA UPDATE'!$T:$T,วิเคราะห์ข้อมูล!$Q$2) -> 0 | R17: =SUMIFS('DATA UPDATE'!$L:$L,'DATA UPDATE'!$D:$D,วิเคราะห์ข้อมูล!A17,'DATA UPDATE'!$T:$T,วิเคราะห์ข้อมูล!$R$2) -> 0 | S17: =SUMIFS('UPDATE STOCK'!$F:$F,'UPDATE STOCK'!$A:$A,A17,'UPDATE STOCK'!$G:$G,$S$2) -> 1 | T17: =SUMIFS('UPDATE STOCK'!$F:$F,'UPDATE STOCK'!$A:$A,A17,'UPDATE STOCK'!$G:$G,$T$2) -> 4 | U17: =SUMIFS('UPDATE STOCK'!$F:$F,'UPDATE STOCK'!$A:$A,วิเคราะห์ข้อมูล!A17,'UPDATE STOCK'!$G:$G,$U$2) -> 3 | V17: =SUMIFS('UPDATE STOCK'!$F:$F,'UPDATE STOCK'!$A:$A,วิเคราะห์ข้อมูล!A17,'UPDATE STOCK'!$G:$G,$V$2) -> 1
... A860: A008-1-1 | B860: จารบีเพลาขับ | C860: =SUMIFS('DATA UPDATE'!$L:$L,'DATA UPDATE'!$E:$E,วิเคราะห์ข้อมูล!A860,'DATA UPDATE'!$B:$B,วิเคราะห์ข้อมูล!$C$2) -> 0 | D860: =SUMIFS('DATA UPDATE'!$L:$L,'DATA UPDATE'!$E:$E,A860,'DATA UPDATE'!$B:$B,$D$2) -> 0 | E860: =SUMIFS('DATA UPDATE'!$L:$L,'DATA UPDATE'!$E:$E,A860,'DATA UPDATE'!$B:$B,$E$2) -> 0 | F860: =SUMIFS('DATA UPDATE'!$L:$L,'DATA UPDATE'!$E:$E,A860,'DATA UPDATE'!$B:$B,$F$2) -> 1 | G860: =SUMIFS('DATA UPDATE'!$L:$L,'DATA UPDATE'!$E:$E,A860,'DATA UPDATE'!$B:$B,$G$2) -> 0 | H860: =SUMIFS('DATA UPDATE'!$L:$L,'DATA UPDATE'!$E:$E,A860,'DATA UPDATE'!$B:$B,$H$2) -> 0 | I860: =SUM(C860:H860) -> 1 | J860: =SUMIFS('UPDATE STOCK'!F:F,'UPDATE STOCK'!A:A,วิเคราะห์ข้อมูล!A860) -> 0 | K860: =MAX(C860:G860) -> 1 | L860: =MIN(C860:G860) -> 0 | M860: =AVERAGE(C860:G860) -> 0.2 | N860: =M860-J860 -> 0.2 | O860: =SUMIFS('DATA UPDATE'!$L:$L,'DATA UPDATE'!$E:$E,วิเคราะห์ข้อมูล!A860,'DATA UPDATE'!$T:$T,วิเคราะห์ข้อมูล!$O$2) -> 0 | P860: =SUMIFS('DATA UPDATE'!$L:$L,'DATA UPDATE'!$E:$E,วิเคราะห์ข้อมูล!A860,'DATA UPDATE'!$T:$T,วิเคราะห์ข้อมูล!$P$2) -> 0 | Q860: =SUMIFS('DATA UPDATE'!$L:$L,'DATA UPDATE'!$E:$E,วิเคราะห์ข้อมูล!A860,'DATA UPDATE'!$T:$T,วิเคราะห์ข้อมูล!$Q$2) -> 0 | R860: =SUMIFS('DATA UPDATE'!$L:$L,'DATA UPDATE'!$D:$D,วิเคราะห์ข้อมูล!A860,'DATA UPDATE'!$T:$T,วิเคราะห์ข้อมูล!$R$2) -> 0 | S860: =SUMIFS('UPDATE STOCK'!$F:$F,'UPDATE STOCK'!$A:$A,A860,'UPDATE STOCK'!$G:$G,$S$2) -> 0 | T860: =SUMIFS('UPDATE STOCK'!$F:$F,'UPDATE STOCK'!$A:$A,A860,'UPDATE STOCK'!$G:$G,$T$2) -> 0 | U860: =SUMIFS('UPDATE STOCK'!$F:$F,'UPDATE STOCK'!$A:$A,วิเคราะห์ข้อมูล!A860,'UPDATE STOCK'!$G:$G,$U$2) -> 0 | V860: =SUMIFS('UPDATE STOCK'!$F:$F,'UPDATE STOCK'!$A:$A,วิเคราะห์ข้อมูล!A860,'UPDATE STOCK'!$G:$G,$V$2) -> 0
A861: 9002 | B861: จำนวนรถเข้า | C861: =SUMIFS('DATA UPDATE'!$L:$L,'DATA UPDATE'!$E:$E,วิเคราะห์ข้อมูล!A861,'DATA UPDATE'!$B:$B,วิเคราะห์ข้อมูล!$C$2) -> 0 | D861: =SUMIFS('DATA UPDATE'!$L:$L,'DATA UPDATE'!$E:$E,A861,'DATA UPDATE'!$B:$B,$D$2) -> 0 | E861: =SUMIFS('DATA UPDATE'!$L:$L,'DATA UPDATE'!$E:$E,A861,'DATA UPDATE'!$B:$B,$E$2) -> 0 | F861: =SUMIFS('DATA UPDATE'!$L:$L,'DATA UPDATE'!$E:$E,A861,'DATA UPDATE'!$B:$B,$F$2) -> 0 | G861: =SUMIFS('DATA UPDATE'!$L:$L,'DATA UPDATE'!$E:$E,A861,'DATA UPDATE'!$B:$B,$G$2) -> 0 | H861: =SUMIFS('DATA UPDATE'!$L:$L,'DATA UPDATE'!$E:$E,A861,'DATA UPDATE'!$B:$B,$H$2) -> 0 | I861: =SUM(C861:H861) -> 0 | J861: =SUMIFS('UPDATE STOCK'!F:F,'UPDATE STOCK'!A:A,วิเคราะห์ข้อมูล!A861) -> 0 | K861: =MAX(C861:G861) -> 0 | L861: =MIN(C861:G861) -> 0 | M861: =AVERAGE(C861:G861) -> 0 | N861: =M861-J861 -> 0 | O861: =SUMIFS('DATA UPDATE'!$L:$L,'DATA UPDATE'!$E:$E,วิเคราะห์ข้อมูล!A861,'DATA UPDATE'!$T:$T,วิเคราะห์ข้อมูล!$O$2) -> 0 | P861: =SUMIFS('DATA UPDATE'!$L:$L,'DATA UPDATE'!$E:$E,วิเคราะห์ข้อมูล!A861,'DATA UPDATE'!$T:$T,วิเคราะห์ข้อมูล!$P$2) -> 0 | Q861: =SUMIFS('DATA UPDATE'!$L:$L,'DATA UPDATE'!$E:$E,วิเคราะห์ข้อมูล!A861,'DATA UPDATE'!$T:$T,วิเคราะห์ข้อมูล!$Q$2) -> 0 | R861: =SUMIFS('DATA UPDATE'!$L:$L,'DATA UPDATE'!$D:$D,วิเคราะห์ข้อมูล!A861,'DATA UPDATE'!$T:$T,วิเคราะห์ข้อมูล!$R$2) -> 0 | S861: =SUMIFS('UPDATE STOCK'!$F:$F,'UPDATE STOCK'!$A:$A,A861,'UPDATE STOCK'!$G:$G,$S$2) -> 0 | T861: =SUMIFS('UPDATE STOCK'!$F:$F,'UPDATE STOCK'!$A:$A,A861,'UPDATE STOCK'!$G:$G,$T$2) -> 0 | U861: =SUMIFS('UPDATE STOCK'!$F:$F,'UPDATE STOCK'!$A:$A,วิเคราะห์ข้อมูล!A861,'UPDATE STOCK'!$G:$G,$U$2) -> 0 | V861: =SUMIFS('UPDATE STOCK'!$F:$F,'UPDATE STOCK'!$A:$A,วิเคราะห์ข้อมูล!A861,'UPDATE STOCK'!$G:$G,$V$2) -> 0
A862: J034 | B862: จุ๊ปเเลส วอนเตอร์ TR415 จุ๊ปหัวโต TATA | C862: =SUMIFS('DATA UPDATE'!$L:$L,'DATA UPDATE'!$E:$E,วิเคราะห์ข้อมูล!A862,'DATA UPDATE'!$B:$B,วิเคราะห์ข้อมูล!$C$2) -> 0 | D862: =SUMIFS('DATA UPDATE'!$L:$L,'DATA UPDATE'!$E:$E,A862,'DATA UPDATE'!$B:$B,$D$2) -> 0 | E862: =SUMIFS('DATA UPDATE'!$L:$L,'DATA UPDATE'!$E:$E,A862,'DATA UPDATE'!$B:$B,$E$2) -> 2 | F862: =SUMIFS('DATA UPDATE'!$L:$L,'DATA UPDATE'!$E:$E,A862,'DATA UPDATE'!$B:$B,$F$2) -> 0 | G862: =SUMIFS('DATA UPDATE'!$L:$L,'DATA UPDATE'!$E:$E,A862,'DATA UPDATE'!$B:$B,$G$2) -> 8 | H862: =SUMIFS('DATA UPDATE'!$L:$L,'DATA UPDATE'!$E:$E,A862,'DATA UPDATE'!$B:$B,$H$2) -> 0 | I862: =SUM(C862:H862) -> 10 | J862: =SUMIFS('UPDATE STOCK'!F:F,'UPDATE STOCK'!A:A,วิเคราะห์ข้อมูล!A862) -> 15 | K862: =MAX(C862:G862) -> 8 | L862: =MIN(C862:G862) -> 0 | M862: =AVERAGE(C862:G862) -> 2 | N862: =M862-J862 -> -13 | O862: =SUMIFS('DATA UPDATE'!$L:$L,'DATA UPDATE'!$E:$E,วิเคราะห์ข้อมูล!A862,'DATA UPDATE'!$T:$T,วิเคราะห์ข้อมูล!$O$2) -> 0 | P862: =SUMIFS('DATA UPDATE'!$L:$L,'DATA UPDATE'!$E:$E,วิเคราะห์ข้อมูล!A862,'DATA UPDATE'!$T:$T,วิเคราะห์ข้อมูล!$P$2) -> 10 | Q862: =SUMIFS('DATA UPDATE'!$L:$L,'DATA UPDATE'!$E:$E,วิเคราะห์ข้อมูล!A862,'DATA UPDATE'!$T:$T,วิเคราะห์ข้อมูล!$Q$2) -> 0 | R862: =SUMIFS('DATA UPDATE'!$L:$L,'DATA UPDATE'!$D:$D,วิเคราะห์ข้อมูล!A862,'DATA UPDATE'!$T:$T,วิเคราะห์ข้อมูล!$R$2) -> 0 | S862: =SUMIFS('UPDATE STOCK'!$F:$F,'UPDATE STOCK'!$A:$A,A862,'UPDATE STOCK'!$G:$G,$S$2) -> 0 | T862: =SUMIFS('UPDATE STOCK'!$F:$F,'UPDATE STOCK'!$A:$A,A862,'UPDATE STOCK'!$G:$G,$T$2) -> 15 | U862: =SUMIFS('UPDATE STOCK'!$F:$F,'UPDATE STOCK'!$A:$A,วิเคราะห์ข้อมูล!A862,'UPDATE STOCK'!$G:$G,$U$2) -> 0 | V862: =SUMIFS('UPDATE STOCK'!$F:$F,'UPDATE STOCK'!$A:$A,วิเคราะห์ข้อมูล!A862,'UPDATE STOCK'!$G:$G,$V$2) -> 0
A863: A340-M4-26 | B863: ชุดเกียร์ MAZDA BT50 | C863: =SUMIFS('DATA UPDATE'!$L:$L,'DATA UPDATE'!$E:$E,วิเคราะห์ข้อมูล!A863,'DATA UPDATE'!$B:$B,วิเคราะห์ข้อมูล!$C$2) -> 0 | D863: =SUMIFS('DATA UPDATE'!$L:$L,'DATA UPDATE'!$E:$E,A863,'DATA UPDATE'!$B:$B,$D$2) -> 1 | E863: =SUMIFS('DATA UPDATE'!$L:$L,'DATA UPDATE'!$E:$E,A863,'DATA UPDATE'!$B:$B,$E$2) -> 0 | F863: =SUMIFS('DATA UPDATE'!$L:$L,'DATA UPDATE'!$E:$E,A863,'DATA UPDATE'!$B:$B,$F$2) -> 0 | G863: =SUMIFS('DATA UPDATE'!$L:$L,'DATA UPDATE'!$E:$E,A863,'DATA UPDATE'!$B:$B,$G$2) -> 0 | H863: =SUMIFS('DATA UPDATE'!$L:$L,'DATA UPDATE'!$E:$E,A863,'DATA UPDATE'!$B:$B,$H$2) -> 0 | I863: =SUM(C863:H863) -> 1 | J863: =SUMIFS('UPDATE STOCK'!F:F,'UPDATE STOCK'!A:A,วิเคราะห์ข้อมูล!A863) -> 0 | K863: =MAX(C863:G863) -> 1 | L863: =MIN(C863:G863) -> 0 | M863: =AVERAGE(C863:G863) -> 0.2 | N863: =M863-J863 -> 0.2 | O863: =SUMIFS('DATA UPDATE'!$L:$L,'DATA UPDATE'!$E:$E,วิเคราะห์ข้อมูล!A863,'DATA UPDATE'!$T:$T,วิเคราะห์ข้อมูล!$O$2) -> 1 | P863: =SUMIFS('DATA UPDATE'!$L:$L,'DATA UPDATE'!$E:$E,วิเคราะห์ข้อมูล!A863,'DATA UPDATE'!$T:$T,วิเคราะห์ข้อมูล!$P$2) -> 0 | Q863: =SUMIFS('DATA UPDATE'!$L:$L,'DATA UPDATE'!$E:$E,วิเคราะห์ข้อมูล!A863,'DATA UPDATE'!$T:$T,วิเคราะห์ข้อมูล!$Q$2) -> 0 | R863: =SUMIFS('DATA UPDATE'!$L:$L,'DATA UPDATE'!$D:$D,วิเคราะห์ข้อมูล!A863,'DATA UPDATE'!$T:$T,วิเคราะห์ข้อมูล!$R$2) -> 0 | S863: =SUMIFS('UPDATE STOCK'!$F:$F,'UPDATE STOCK'!$A:$A,A863,'UPDATE STOCK'!$G:$G,$S$2) -> 0 | T863: =SUMIFS('UPDATE STOCK'!$F:$F,'UPDATE STOCK'!$A:$A,A863,'UPDATE STOCK'!$G:$G,$T$2) -> 0 | U863: =SUMIFS('UPDATE STOCK'!$F:$F,'UPDATE STOCK'!$A:$A,วิเคราะห์ข้อมูล!A863,'UPDATE STOCK'!$G:$G,$U$2) -> 0 | V863: =SUMIFS('UPDATE STOCK'!$F:$F,'UPDATE STOCK'!$A:$A,วิเคราะห์ข้อมูล!A863,'UPDATE STOCK'!$G:$G,$V$2) -> 0
A864: A340-T2-352 | B864: ชุดกิ๊บล็อคผ้าเบรค TOYOTA REVO ปี 2020 | C864: =SUMIFS('DATA UPDATE'!$L:$L,'DATA UPDATE'!$E:$E,วิเคราะห์ข้อมูล!A864,'DATA UPDATE'!$B:$B,วิเคราะห์ข้อมูล!$C$2) -> 1 | D864: =SUMIFS('DATA UPDATE'!$L:$L,'DATA UPDATE'!$E:$E,A864,'DATA UPDATE'!$B:$B,$D$2) -> 0 | E864: =SUMIFS('DATA UPDATE'!$L:$L,'DATA UPDATE'!$E:$E,A864,'DATA UPDATE'!$B:$B,$E$2) -> 0 | F864: =SUMIFS('DATA UPDATE'!$L:$L,'DATA UPDATE'!$E:$E,A864,'DATA UPDATE'!$B:$B,$F$2) -> 0 | G864: =SUMIFS('DATA UPDATE'!$L:$L,'DATA UPDATE'!$E:$E,A864,'DATA UPDATE'!$B:$B,$G$2) -> 0 | H864: =SUMIFS('DATA UPDATE'!$L:$L,'DATA UPDATE'!$E:$E,A864,'DATA UPDATE'!$B:$B,$H$2) -> 0 | I864: =SUM(C864:H864) -> 1 | J864: =SUMIFS('UPDATE STOCK'!F:F,'UPDATE STOCK'!A:A,วิเคราะห์ข้อมูล!A864) -> 0 | K864: =MAX(C864:G864) -> 1 | L864: =MIN(C864:G864) -> 0 | M864: =AVERAGE(C864:G864) -> 0.2 | N864: =M864-J864 -> 0.2 | O864: =SUMIFS('DATA UPDATE'!$L:$L,'DATA UPDATE'!$E:$E,วิเคราะห์ข้อมูล!A864,'DATA UPDATE'!$T:$T,วิเคราะห์ข้อมูล!$O$2) -> 0 | P864: =SUMIFS('DATA UPDATE'!$L:$L,'DATA UPDATE'!$E:$E,วิเคราะห์ข้อมูล!A864,'DATA UPDATE'!$T:$T,วิเคราะห์ข้อมูล!$P$2) -> 0 | Q864: =SUMIFS('DATA UPDATE'!$L:$L,'DATA UPDATE'!$E:$E,วิเคราะห์ข้อมูล!A864,'DATA UPDATE'!$T:$T,วิเคราะห์ข้อมูล!$Q$2) -> 1 | R864: =SUMIFS('DATA UPDATE'!$L:$L,'DATA UPDATE'!$D:$D,วิเคราะห์ข้อมูล!A864,'DATA UPDATE'!$T:$T,วิเคราะห์ข้อมูล!$R$2) -> 0 | S864: =SUMIFS('UPDATE STOCK'!$F:$F,'UPDATE STOCK'!$A:$A,A864,'UPDATE STOCK'!$G:$G,$S$2) -> 0 | T864: =SUMIFS('UPDATE STOCK'!$F:$F,'UPDATE STOCK'!$A:$A,A864,'UPDATE STOCK'!$G:$G,$T$2) -> 0 | U864: =SUMIFS('UPDATE STOCK'!$F:$F,'UPDATE STOCK'!$A:$A,วิเคราะห์ข้อมูล!A864,'UPDATE STOCK'!$G:$G,$U$2) -> 0 | V864: =SUMIFS('UPDATE STOCK'!$F:$F,'UPDATE STOCK'!$A:$A,วิเคราะห์ข้อมูล!A864,'UPDATE STOCK'!$G:$G,$V$2) -> 0
A865: A048-M4-2 | B865: ชุดซ่อม M/D BT50 | C865: =SUMIFS('DATA UPDATE'!$L:$L,'DATA UPDATE'!$E:$E,วิเคราะห์ข้อมูล!A865,'DATA UPDATE'!$B:$B,วิเคราะห์ข้อมูล!$C$2) -> 0 | D865: =SUMIFS('DATA UPDATE'!$L:$L,'DATA UPDATE'!$E:$E,A865,'DATA UPDATE'!$B:$B,$D$2) -> 1 | E865: =SUMIFS('DATA UPDATE'!$L:$L,'DATA UPDATE'!$E:$E,A865,'DATA UPDATE'!$B:$B,$E$2) -> 0 | F865: =SUMIFS('DATA UPDATE'!$L:$L,'DATA UPDATE'!$E:$E,A865,'DATA UPDATE'!$B:$B,$F$2) -> 0 | G865: =SUMIFS('DATA UPDATE'!$L:$L,'DATA UPDATE'!$E:$E,A865,'DATA UPDATE'!$B:$B,$G$2) -> 0 | H865: =SUMIFS('DATA UPDATE'!$L:$L,'DATA UPDATE'!$E:$E,A865,'DATA UPDATE'!$B:$B,$H$2) -> 0 | I865: =SUM(C865:H865) -> 1 | J865: =SUMIFS('UPDATE STOCK'!F:F,'UPDATE STOCK'!A:A,วิเคราะห์ข้อมูล!A865) -> 0 | K865: =MAX(C865:G865) -> 1 | L865: =MIN(C865:G865) -> 0 | M865: =AVERAGE(C865:G865) -> 0.2 | N865: =M865-J865 -> 0.2 | O865: =SUMIFS('DATA UPDATE'!$L:$L,'DATA UPDATE'!$E:$E,วิเคราะห์ข้อมูล!A865,'DATA UPDATE'!$T:$T,วิเคราะห์ข้อมูล!$O$2) -> 0 | P865: =SUMIFS('DATA UPDATE'!$L:$L,'DATA UPDATE'!$E:$E,วิเคราะห์ข้อมูล!A865,'DATA UPDATE'!$T:$T,วิเคราะห์ข้อมูล!$P$2) -> 0 | Q865: =SUMIFS('DATA UPDATE'!$L:$L,'DATA UPDATE'!$E:$E,วิเคราะห์ข้อมูล!A865,'DATA UPDATE'!$T:$T,วิเคราะห์ข้อมูล!$Q$2) -> 1 | R865: =SUMIFS('DATA UPDATE'!$L:$L,'DATA UPDATE'!$D:$D,วิเคราะห์ข้อมูล!A865,'DATA UPDATE'!$T:$T,วิเคราะห์ข้อมูล!$R$2) -> 0 | S865: =SUMIFS('UPDATE STOCK'!$F:$F,'UPDATE STOCK'!$A:$A,A865,'UPDATE STOCK'!$G:$G,$S$2) -> 0 | T865: =SUMIFS('UPDATE STOCK'!$F:$F,'UPDATE STOCK'!$A:$A,A865,'UPDATE STOCK'!$G:$G,$T$2) -> 0 | U865: =SUMIFS('UPDATE STOCK'!$F:$F,'UPDATE STOCK'!$A:$A,วิเคราะห์ข้อมูล!A865,'UPDATE STOCK'!$G:$G,$U$2) -> 0 | V865: =SUMIFS('UPDATE STOCK'!$F:$F,'UPDATE STOCK'!$A:$A,วิเคราะห์ข้อมูล!A865,'UPDATE STOCK'!$G:$G,$V$2) -> 0
A866: A048-T2-16 | B866: ชุดซ่อมเบรค T/Y REVO ปี 2010-2020 (YBK) | C866: =SUMIFS('DATA UPDATE'!$L:$L,'DATA UPDATE'!$E:$E,วิเคราะห์ข้อมูล!A866,'DATA UPDATE'!$B:$B,วิเคราะห์ข้อมูล!$C$2) -> 1 | D866: =SUMIFS('DATA UPDATE'!$L:$L,'DATA UPDATE'!$E:$E,A866,'DATA UPDATE'!$B:$B,$D$2) -> 0 | E866: =SUMIFS('DATA UPDATE'!$L:$L,'DATA UPDATE'!$E:$E,A866,'DATA UPDATE'!$B:$B,$E$2) -> 0 | F866: =SUMIFS('DATA UPDATE'!$L:$L,'DATA UPDATE'!$E:$E,A866,'DATA UPDATE'!$B:$B,$F$2) -> 0 | G866: =SUMIFS('DATA UPDATE'!$L:$L,'DATA UPDATE'!$E:$E,A866,'DATA UPDATE'!$B:$B,$G$2) -> 0 | H866: =SUMIFS('DATA UPDATE'!$L:$L,'DATA UPDATE'!$E:$E,A866,'DATA UPDATE'!$B:$B,$H$2) -> 0 | I866: =SUM(C866:H866) -> 1 | J866: =SUMIFS('UPDATE STOCK'!F:F,'UPDATE STOCK'!A:A,วิเคราะห์ข้อมูล!A866) -> 0 | K866: =MAX(C866:G866) -> 1 | L866: =MIN(C866:G866) -> 0 | M866: =AVERAGE(C866:G866) -> 0.2 | N866: =M866-J866 -> 0.2 | O866: =SUMIFS('DATA UPDATE'!$L:$L,'DATA UPDATE'!$E:$E,วิเคราะห์ข้อมูล!A866,'DATA UPDATE'!$T:$T,วิเคราะห์ข้อมูล!$O$2) -> 0 | P866: =SUMIFS('DATA UPDATE'!$L:$L,'DATA UPDATE'!$E:$E,วิเคราะห์ข้อมูล!A866,'DATA UPDATE'!$T:$T,วิเคราะห์ข้อมูล!$P$2) -> 0 | Q866: =SUMIFS('DATA UPDATE'!$L:$L,'DATA UPDATE'!$E:$E,วิเคราะห์ข้อมูล!A866,'DATA UPDATE'!$T:$T,วิเคราะห์ข้อมูล!$Q$2) -> 1 | R866: =SUMIFS('DATA UPDATE'!$L:$L,'DATA UPDATE'!$D:$D,วิเคราะห์ข้อมูล!A866,'DATA UPDATE'!$T:$T,วิเคราะห์ข้อมูล!$R$2) -> 0 | S866: =SUMIFS('UPDATE STOCK'!$F:$F,'UPDATE STOCK'!$A:$A,A866,'UPDATE STOCK'!$G:$G,$S$2) -> 0 | T866: =SUMIFS('UPDATE STOCK'!$F:$F,'UPDATE STOCK'!$A:$A,A866,'UPDATE STOCK'!$G:$G,$T$2) -> 0 | U866: =SUMIFS('UPDATE STOCK'!$F:$F,'UPDATE STOCK'!$A:$A,วิเคราะห์ข้อมูล!A866,'UPDATE STOCK'!$G:$G,$U$2) -> 0 | V866: =SUMIFS('UPDATE STOCK'!$F:$F,'UPDATE STOCK'!$A:$A,วิเคราะห์ข้อมูล!A866,'UPDATE STOCK'!$G:$G,$V$2) -> 0
A867: A048-T2-62 | B867: ชุดซ่อมเบรค TOYOTA REVO ปี 2020 | C867: =SUMIFS('DATA UPDATE'!$L:$L,'DATA UPDATE'!$E:$E,วิเคราะห์ข้อมูล!A867,'DATA UPDATE'!$B:$B,วิเคราะห์ข้อมูล!$C$2) -> 1 | D867: =SUMIFS('DATA UPDATE'!$L:$L,'DATA UPDATE'!$E:$E,A867,'DATA UPDATE'!$B:$B,$D$2) -> 0 | E867: =SUMIFS('DATA UPDATE'!$L:$L,'DATA UPDATE'!$E:$E,A867,'DATA UPDATE'!$B:$B,$E$2) -> 0 | F867: =SUMIFS('DATA UPDATE'!$L:$L,'DATA UPDATE'!$E:$E,A867,'DATA UPDATE'!$B:$B,$F$2) -> 0 | G867: =SUMIFS('DATA UPDATE'!$L:$L,'DATA UPDATE'!$E:$E,A867,'DATA UPDATE'!$B:$B,$G$2) -> 0 | H867: =SUMIFS('DATA UPDATE'!$L:$L,'DATA UPDATE'!$E:$E,A867,'DATA UPDATE'!$B:$B,$H$2) -> 0 | I867: =SUM(C867:H867) -> 1 | J867: =SUMIFS('UPDATE STOCK'!F:F,'UPDATE STOCK'!A:A,วิเคราะห์ข้อมูล!A867) -> 0 | K867: =MAX(C867:G867) -> 1 | L867: =MIN(C867:G867) -> 0 | M867: =AVERAGE(C867:G867) -> 0.2 | N867: =M867-J867 -> 0.2 | O867: =SUMIFS('DATA UPDATE'!$L:$L,'DATA UPDATE'!$E:$E,วิเคราะห์ข้อมูล!A867,'DATA UPDATE'!$T:$T,วิเคราะห์ข้อมูล!$O$2) -> 0 | P867: =SUMIFS('DATA UPDATE'!$L:$L,'DATA UPDATE'!$E:$E,วิเคราะห์ข้อมูล!A867,'DATA UPDATE'!$T:$T,วิเคราะห์ข้อมูล!$P$2) -> 0 | Q867: =SUMIFS('DATA UPDATE'!$L:$L,'DATA UPDATE'!$E:$E,วิเคราะห์ข้อมูล!A867,'DATA UPDATE'!$T:$T,วิเคราะห์ข้อมูล!$Q$2) -> 1 | R867: =SUMIFS('DATA UPDATE'!$L:$L,'DATA UPDATE'!$D:$D,วิเคราะห์ข้อมูล!A867,'DATA UPDATE'!$T:$T,วิเคราะห์ข้อมูล!$R$2) -> 0 | S867: =SUMIFS('UPDATE STOCK'!$F:$F,'UPDATE STOCK'!$A:$A,A867,'UPDATE STOCK'!$G:$G,$S$2) -> 0 | T867: =SUMIFS('UPDATE STOCK'!$F:$F,'UPDATE STOCK'!$A:$A,A867,'UPDATE STOCK'!$G:$G,$T$2) -> 0 | U867: =SUMIFS('UPDATE STOCK'!$F:$F,'UPDATE STOCK'!$A:$A,วิเคราะห์ข้อมูล!A867,'UPDATE STOCK'!$G:$G,$U$2) -> 0 | V867: =SUMIFS('UPDATE STOCK'!$F:$F,'UPDATE STOCK'!$A:$A,วิเคราะห์ข้อมูล!A867,'UPDATE STOCK'!$G:$G,$V$2) -> 0
A868: A048-T2-63 | B868: ชุดซ่อมไดร์ชารจ์ T/Y REVO | C868: =SUMIFS('DATA UPDATE'!$L:$L,'DATA UPDATE'!$E:$E,วิเคราะห์ข้อมูล!A868,'DATA UPDATE'!$B:$B,วิเคราะห์ข้อมูล!$C$2) -> 0 | D868: =SUMIFS('DATA UPDATE'!$L:$L,'DATA UPDATE'!$E:$E,A868,'DATA UPDATE'!$B:$B,$D$2) -> 1 | E868: =SUMIFS('DATA UPDATE'!$L:$L,'DATA UPDATE'!$E:$E,A868,'DATA UPDATE'!$B:$B,$E$2) -> 0 | F868: =SUMIFS('DATA UPDATE'!$L:$L,'DATA UPDATE'!$E:$E,A868,'DATA UPDATE'!$B:$B,$F$2) -> 0 | G868: =SUMIFS('DATA UPDATE'!$L:$L,'DATA UPDATE'!$E:$E,A868,'DATA UPDATE'!$B:$B,$G$2) -> 0 | H868: =SUMIFS('DATA UPDATE'!$L:$L,'DATA UPDATE'!$E:$E,A868,'DATA UPDATE'!$B:$B,$H$2) -> 0 | I868: =SUM(C868:H868) -> 1 | J868: =SUMIFS('UPDATE STOCK'!F:F,'UPDATE STOCK'!A:A,วิเคราะห์ข้อมูล!A868) -> 0 | K868: =MAX(C868:G868) -> 1 | L868: =MIN(C868:G868) -> 0 | M868: =AVERAGE(C868:G868) -> 0.2 | N868: =M868-J868 -> 0.2 | O868: =SUMIFS('DATA UPDATE'!$L:$L,'DATA UPDATE'!$E:$E,วิเคราะห์ข้อมูล!A868,'DATA UPDATE'!$T:$T,วิเคราะห์ข้อมูล!$O$2) -> 1 | P868: =SUMIFS('DATA UPDATE'!$L:$L,'DATA UPDATE'!$E:$E,วิเคราะห์ข้อมูล!A868,'DATA UPDATE'!$T:$T,วิเคราะห์ข้อมูล!$P$2) -> 0 | Q868: =SUMIFS('DATA UPDATE'!$L:$L,'DATA UPDATE'!$E:$E,วิเคราะห์ข้อมูล!A868,'DATA UPDATE'!$T:$T,วิเคราะห์ข้อมูล!$Q$2) -> 0 | R868: =SUMIFS('DATA UPDATE'!$L:$L,'DATA UPDATE'!$D:$D,วิเคราะห์ข้อมูล!A868,'DATA UPDATE'!$T:$T,วิเคราะห์ข้อมูล!$R$2) -> 0 | S868: =SUMIFS('UPDATE STOCK'!$F:$F,'UPDATE STOCK'!$A:$A,A868,'UPDATE STOCK'!$G:$G,$S$2) -> 0 | T868: =SUMIFS('UPDATE STOCK'!$F:$F,'UPDATE STOCK'!$A:$A,A868,'UPDATE STOCK'!$G:$G,$T$2) -> 0 | U868: =SUMIFS('UPDATE STOCK'!$F:$F,'UPDATE STOCK'!$A:$A,วิเคราะห์ข้อมูล!A868,'UPDATE STOCK'!$G:$G,$U$2) -> 0 | V868: =SUMIFS('UPDATE STOCK'!$F:$F,'UPDATE STOCK'!$A:$A,วิเคราะห์ข้อมูล!A868,'UPDATE STOCK'!$G:$G,$V$2) -> 0
A869: A048-H11-6 | B869: ชุดซ่อมดิสเบรค H/D CITY ปี 2010-2020 | C869: =SUMIFS('DATA UPDATE'!$L:$L,'DATA UPDATE'!$E:$E,วิเคราะห์ข้อมูล!A869,'DATA UPDATE'!$B:$B,วิเคราะห์ข้อมูล!$C$2) -> 0 | D869: =SUMIFS('DATA UPDATE'!$L:$L,'DATA UPDATE'!$E:$E,A869,'DATA UPDATE'!$B:$B,$D$2) -> 0 | E869: =SUMIFS('DATA UPDATE'!$L:$L,'DATA UPDATE'!$E:$E,A869,'DATA UPDATE'!$B:$B,$E$2) -> 0 | F869: =SUMIFS('DATA UPDATE'!$L:$L,'DATA UPDATE'!$E:$E,A869,'DATA UPDATE'!$B:$B,$F$2) -> 0 | G869: =SUMIFS('DATA UPDATE'!$L:$L,'DATA UPDATE'!$E:$E,A869,'DATA UPDATE'!$B:$B,$G$2) -> 0 | H869: =SUMIFS('DATA UPDATE'!$L:$L,'DATA UPDATE'!$E:$E,A869,'DATA UPDATE'!$B:$B,$H$2) -> 1 | I869: =SUM(C869:H869) -> 1 | J869: =SUMIFS('UPDATE STOCK'!F:F,'UPDATE STOCK'!A:A,วิเคราะห์ข้อมูล!A869) -> 0 | K869: =MAX(C869:G869) -> 0 | L869: =MIN(C869:G869) -> 0 | M869: =AVERAGE(C869:G869) -> 0 | N869: =M869-J869 -> 0 | O869: =SUMIFS('DATA UPDATE'!$L:$L,'DATA UPDATE'!$E:$E,วิเคราะห์ข้อมูล!A869,'DATA UPDATE'!$T:$T,วิเคราะห์ข้อมูล!$O$2) -> 1 | P869: =SUMIFS('DATA UPDATE'!$L:$L,'DATA UPDATE'!$E:$E,วิเคราะห์ข้อมูล!A869,'DATA UPDATE'!$T:$T,วิเคราะห์ข้อมูล!$P$2) -> 0 | Q869: =SUMIFS('DATA UPDATE'!$L:$L,'DATA UPDATE'!$E:$E,วิเคราะห์ข้อมูล!A869,'DATA UPDATE'!$T:$T,วิเคราะห์ข้อมูล!$Q$2) -> 0 | R869: =SUMIFS('DATA UPDATE'!$L:$L,'DATA UPDATE'!$D:$D,วิเคราะห์ข้อมูล!A869,'DATA UPDATE'!$T:$T,วิเคราะห์ข้อมูล!$R$2) -> 0 | S869: =SUMIFS('UPDATE STOCK'!$F:$F,'UPDATE STOCK'!$A:$A,A869,'UPDATE STOCK'!$G:$G,$S$2) -> 0 | T869: =SUMIFS('UPDATE STOCK'!$F:$F,'UPDATE STOCK'!$A:$A,A869,'UPDATE STOCK'!$G:$G,$T$2) -> 0 | U869: =SUMIFS('UPDATE STOCK'!$F:$F,'UPDATE STOCK'!$A:$A,วิเคราะห์ข้อมูล!A869,'UPDATE STOCK'!$G:$G,$U$2) -> 0 | V869: =SUMIFS('UPDATE STOCK'!$F:$F,'UPDATE STOCK'!$A:$A,วิเคราะห์ข้อมูล!A869,'UPDATE STOCK'!$G:$G,$V$2) -> 0
A870: A048-N3-3 | B870: ชุดซ่อมดิสเบรค N/S NAVARA NP300 | C870: =SUMIFS('DATA UPDATE'!$L:$L,'DATA UPDATE'!$E:$E,วิเคราะห์ข้อมูล!A870,'DATA UPDATE'!$B:$B,วิเคราะห์ข้อมูล!$C$2) -> 0 | D870: =SUMIFS('DATA UPDATE'!$L:$L,'DATA UPDATE'!$E:$E,A870,'DATA UPDATE'!$B:$B,$D$2) -> 1 | E870: =SUMIFS('DATA UPDATE'!$L:$L,'DATA UPDATE'!$E:$E,A870,'DATA UPDATE'!$B:$B,$E$2) -> 0 | F870: =SUMIFS('DATA UPDATE'!$L:$L,'DATA UPDATE'!$E:$E,A870,'DATA UPDATE'!$B:$B,$F$2) -> 0 | G870: =SUMIFS('DATA UPDATE'!$L:$L,'DATA UPDATE'!$E:$E,A870,'DATA UPDATE'!$B:$B,$G$2) -> 0 | H870: =SUMIFS('DATA UPDATE'!$L:$L,'DATA UPDATE'!$E:$E,A870,'DATA UPDATE'!$B:$B,$H$2) -> 0 | I870: =SUM(C870:H870) -> 1 | J870: =SUMIFS('UPDATE STOCK'!F:F,'UPDATE STOCK'!A:A,วิเคราะห์ข้อมูล!A870) -> 0 | K870: =MAX(C870:G870) -> 1 | L870: =MIN(C870:G870) -> 0 | M870: =AVERAGE(C870:G870) -> 0.2 | N870: =M870-J870 -> 0.2 | O870: =SUMIFS('DATA UPDATE'!$L:$L,'DATA UPDATE'!$E:$E,วิเคราะห์ข้อมูล!A870,'DATA UPDATE'!$T:$T,วิเคราะห์ข้อมูล!$O$2) -> 1 | P870: =SUMIFS('DATA UPDATE'!$L:$L,'DATA UPDATE'!$E:$E,วิเคราะห์ข้อมูล!A870,'DATA UPDATE'!$T:$T,วิเคราะห์ข้อมูล!$P$2) -> 0 | Q870: =SUMIFS('DATA UPDATE'!$L:$L,'DATA UPDATE'!$E:$E,วิเคราะห์ข้อมูล!A870,'DATA UPDATE'!$T:$T,วิเคราะห์ข้อมูล!$Q$2) -> 0 | R870: =SUMIFS('DATA UPDATE'!$L:$L,'DATA UPDATE'!$D:$D,วิเคราะห์ข้อมูล!A870,'DATA UPDATE'!$T:$T,วิเคราะห์ข้อมูล!$R$2) -> 0 | S870: =SUMIFS('UPDATE STOCK'!$F:$F,'UPDATE STOCK'!$A:$A,A870,'UPDATE STOCK'!$G:$G,$S$2) -> 0 | T870: =SUMIFS('UPDATE STOCK'!$F:$F,'UPDATE STOCK'!$A:$A,A870,'UPDATE STOCK'!$G:$G,$T$2) -> 0 | U870: =SUMIFS('UPDATE STOCK'!$F:$F,'UPDATE STOCK'!$A:$A,วิเคราะห์ข้อมูล!A870,'UPDATE STOCK'!$G:$G,$U$2) -> 0 | V870: =SUMIFS('UPDATE STOCK'!$F:$F,'UPDATE STOCK'!$A:$A,วิเคราะห์ข้อมูล!A870,'UPDATE STOCK'!$G:$G,$V$2) -> 0
A871: 308-I5-27 | B871: ชุดสลักเพลาหน้า MRK NPR'06^NPR501 MRK-MI-11 | C871: =SUMIFS('DATA UPDATE'!$L:$L,'DATA UPDATE'!$E:$E,วิเคราะห์ข้อมูล!A871,'DATA UPDATE'!$B:$B,วิเคราะห์ข้อมูล!$C$2) -> 0 | D871: =SUMIFS('DATA UPDATE'!$L:$L,'DATA UPDATE'!$E:$E,A871,'DATA UPDATE'!$B:$B,$D$2) -> 1 | E871: =SUMIFS('DATA UPDATE'!$L:$L,'DATA UPDATE'!$E:$E,A871,'DATA UPDATE'!$B:$B,$E$2) -> 0 | F871: =SUMIFS('DATA UPDATE'!$L:$L,'DATA UPDATE'!$E:$E,A871,'DATA UPDATE'!$B:$B,$F$2) -> 0 | G871: =SUMIFS('DATA UPDATE'!$L:$L,'DATA UPDATE'!$E:$E,A871,'DATA UPDATE'!$B:$B,$G$2) -> 0 | H871: =SUMIFS('DATA UPDATE'!$L:$L,'DATA UPDATE'!$E:$E,A871,'DATA UPDATE'!$B:$B,$H$2) -> 0 | I871: =SUM(C871:H871) -> 1 | J871: =SUMIFS('UPDATE STOCK'!F:F,'UPDATE STOCK'!A:A,วิเคราะห์ข้อมูล!A871) -> 3 | K871: =MAX(C871:G871) -> 1 | L871: =MIN(C871:G871) -> 0 | M871: =AVERAGE(C871:G871) -> 0.2 | N871: =M871-J871 -> -2.8 | O871: =SUMIFS('DATA UPDATE'!$L:$L,'DATA UPDATE'!$E:$E,วิเคราะห์ข้อมูล!A871,'DATA UPDATE'!$T:$T,วิเคราะห์ข้อมูล!$O$2) -> 1 | P871: =SUMIFS('DATA UPDATE'!$L:$L,'DATA UPDATE'!$E:$E,วิเคราะห์ข้อมูล!A871,'DATA UPDATE'!$T:$T,วิเคราะห์ข้อมูล!$P$2) -> 0 | Q871: =SUMIFS('DATA UPDATE'!$L:$L,'DATA UPDATE'!$E:$E,วิเคราะห์ข้อมูล!A871,'DATA UPDATE'!$T:$T,วิเคราะห์ข้อมูล!$Q$2) -> 0 | R871: =SUMIFS('DATA UPDATE'!$L:$L,'DATA UPDATE'!$D:$D,วิเคราะห์ข้อมูล!A871,'DATA UPDATE'!$T:$T,วิเคราะห์ข้อมูล!$R$2) -> 0 | S871: =SUMIFS('UPDATE STOCK'!$F:$F,'UPDATE STOCK'!$A:$A,A871,'UPDATE STOCK'!$G:$G,$S$2) -> 3 | T871: =SUMIFS('UPDATE STOCK'!$F:$F,'UPDATE STOCK'!$A:$A,A871,'UPDATE STOCK'!$G:$G,$T$2) -> 0 | U871: =SUMIFS('UPDATE STOCK'!$F:$F,'UPDATE STOCK'!$A:$A,วิเคราะห์ข้อมูล!A871,'UPDATE STOCK'!$G:$G,$U$2) -> 0 | V871: =SUMIFS('UPDATE STOCK'!$F:$F,'UPDATE STOCK'!$A:$A,วิเคราะห์ข้อมูล!A871,'UPDATE STOCK'!$G:$G,$V$2) -> 0
A872: A039-T2-37 | B872: ซีลเพลาขับ T/Y ALTIS | C872: =SUMIFS('DATA UPDATE'!$L:$L,'DATA UPDATE'!$E:$E,วิเคราะห์ข้อมูล!A872,'DATA UPDATE'!$B:$B,วิเคราะห์ข้อมูล!$C$2) -> 0 | D872: =SUMIFS('DATA UPDATE'!$L:$L,'DATA UPDATE'!$E:$E,A872,'DATA UPDATE'!$B:$B,$D$2) -> 0 | E872: =SUMIFS('DATA UPDATE'!$L:$L,'DATA UPDATE'!$E:$E,A872,'DATA UPDATE'!$B:$B,$E$2) -> 0 | F872: =SUMIFS('DATA UPDATE'!$L:$L,'DATA UPDATE'!$E:$E,A872,'DATA UPDATE'!$B:$B,$F$2) -> 1 | G872: =SUMIFS('DATA UPDATE'!$L:$L,'DATA UPDATE'!$E:$E,A872,'DATA UPDATE'!$B:$B,$G$2) -> 0 | H872: =SUMIFS('DATA UPDATE'!$L:$L,'DATA UPDATE'!$E:$E,A872,'DATA UPDATE'!$B:$B,$H$2) -> 0 | I872: =SUM(C872:H872) -> 1 | J872: =SUMIFS('UPDATE STOCK'!F:F,'UPDATE STOCK'!A:A,วิเคราะห์ข้อมูล!A872) -> 0 | K872: =MAX(C872:G872) -> 1 | L872: =MIN(C872:G872) -> 0 | M872: =AVERAGE(C872:G872) -> 0.2 | N872: =M872-J872 -> 0.2 | O872: =SUMIFS('DATA UPDATE'!$L:$L,'DATA UPDATE'!$E:$E,วิเคราะห์ข้อมูล!A872,'DATA UPDATE'!$T:$T,วิเคราะห์ข้อมูล!$O$2) -> 0 | P872: =SUMIFS('DATA UPDATE'!$L:$L,'DATA UPDATE'!$E:$E,วิเคราะห์ข้อมูล!A872,'DATA UPDATE'!$T:$T,วิเคราะห์ข้อมูล!$P$2) -> 0 | Q872: =SUMIFS('DATA UPDATE'!$L:$L,'DATA UPDATE'!$E:$E,วิเคราะห์ข้อมูล!A872,'DATA UPDATE'!$T:$T,วิเคราะห์ข้อมูล!$Q$2) -> 0 | R872: =SUMIFS('DATA UPDATE'!$L:$L,'DATA UPDATE'!$D:$D,วิเคราะห์ข้อมูล!A872,'DATA UPDATE'!$T:$T,วิเคราะห์ข้อมูล!$R$2) -> 0 | S872: =SUMIFS('UPDATE STOCK'!$F:$F,'UPDATE STOCK'!$A:$A,A872,'UPDATE STOCK'!$G:$G,$S$2) -> 0 | T872: =SUMIFS('UPDATE STOCK'!$F:$F,'UPDATE STOCK'!$A:$A,A872,'UPDATE STOCK'!$G:$G,$T$2) -> 0 | U872: =SUMIFS('UPDATE STOCK'!$F:$F,'UPDATE STOCK'!$A:$A,วิเคราะห์ข้อมูล!A872,'UPDATE STOCK'!$G:$G,$U$2) -> 0 | V872: =SUMIFS('UPDATE STOCK'!$F:$F,'UPDATE STOCK'!$A:$A,วิเคราะห์ข้อมูล!A872,'UPDATE STOCK'!$G:$G,$V$2) -> 0
A873: A039-T2-76 | B873: ซีลราวลิ้น T/Y VIGO COMMUTER ปี 2010-2020 | C873: =SUMIFS('DATA UPDATE'!$L:$L,'DATA UPDATE'!$E:$E,วิเคราะห์ข้อมูล!A873,'DATA UPDATE'!$B:$B,วิเคราะห์ข้อมูล!$C$2) -> 0 | D873: =SUMIFS('DATA UPDATE'!$L:$L,'DATA UPDATE'!$E:$E,A873,'DATA UPDATE'!$B:$B,$D$2) -> 0 | E873: =SUMIFS('DATA UPDATE'!$L:$L,'DATA UPDATE'!$E:$E,A873,'DATA UPDATE'!$B:$B,$E$2) -> 0 | F873: =SUMIFS('DATA UPDATE'!$L:$L,'DATA UPDATE'!$E:$E,A873,'DATA UPDATE'!$B:$B,$F$2) -> 0 | G873: =SUMIFS('DATA UPDATE'!$L:$L,'DATA UPDATE'!$E:$E,A873,'DATA UPDATE'!$B:$B,$G$2) -> 1 | H873: =SUMIFS('DATA UPDATE'!$L:$L,'DATA UPDATE'!$E:$E,A873,'DATA UPDATE'!$B:$B,$H$2) -> 0 | I873: =SUM(C873:H873) -> 1 | J873: =SUMIFS('UPDATE STOCK'!F:F,'UPDATE STOCK'!A:A,วิเคราะห์ข้อมูล!A873) -> 0 | K873: =MAX(C873:G873) -> 1 | L873: =MIN(C873:G873) -> 0 | M873: =AVERAGE(C873:G873) -> 0.2 | N873: =M873-J873 -> 0.2 | O873: =SUMIFS('DATA UPDATE'!$L:$L,'DATA UPDATE'!$E:$E,วิเคราะห์ข้อมูล!A873,'DATA UPDATE'!$T:$T,วิเคราะห์ข้อมูล!$O$2) -> 0 | P873: =SUMIFS('DATA UPDATE'!$L:$L,'DATA UPDATE'!$E:$E,วิเคราะห์ข้อมูล!A873,'DATA UPDATE'!$T:$T,วิเคราะห์ข้อมูล!$P$2) -> 1 | Q873: =SUMIFS('DATA UPDATE'!$L:$L,'DATA UPDATE'!$E:$E,วิเคราะห์ข้อมูล!A873,'DATA UPDATE'!$T:$T,วิเคราะห์ข้อมูล!$Q$2) -> 0 | R873: =SUMIFS('DATA UPDATE'!$L:$L,'DATA UPDATE'!$D:$D,วิเคราะห์ข้อมูล!A873,'DATA UPDATE'!$T:$T,วิเคราะห์ข้อมูล!$R$2) -> 0 | S873: =SUMIFS('UPDATE STOCK'!$F:$F,'UPDATE STOCK'!$A:$A,A873,'UPDATE STOCK'!$G:$G,$S$2) -> 0 | T873: =SUMIFS('UPDATE STOCK'!$F:$F,'UPDATE STOCK'!$A:$A,A873,'UPDATE STOCK'!$G:$G,$T$2) -> 0 | U873: =SUMIFS('UPDATE STOCK'!$F:$F,'UPDATE STOCK'!$A:$A,วิเคราะห์ข้อมูล!A873,'UPDATE STOCK'!$G:$G,$U$2) -> 0 | V873: =SUMIFS('UPDATE STOCK'!$F:$F,'UPDATE STOCK'!$A:$A,วิเคราะห์ข้อมูล!A873,'UPDATE STOCK'!$G:$G,$V$2) -> 0
... A1295: A340-M1-21 | B1295: อ่างน้ำมันเครื่อง M/B TRITON | C1295: =SUMIFS('DATA UPDATE'!$L:$L,'DATA UPDATE'!$E:$E,วิเคราะห์ข้อมูล!A1295,'DATA UPDATE'!$B:$B,วิเคราะห์ข้อมูล!$C$2) -> 0 | D1295: =SUMIFS('DATA UPDATE'!$L:$L,'DATA UPDATE'!$E:$E,A1295,'DATA UPDATE'!$B:$B,$D$2) -> 0 | E1295: =SUMIFS('DATA UPDATE'!$L:$L,'DATA UPDATE'!$E:$E,A1295,'DATA UPDATE'!$B:$B,$E$2) -> 0 | F1295: =SUMIFS('DATA UPDATE'!$L:$L,'DATA UPDATE'!$E:$E,A1295,'DATA UPDATE'!$B:$B,$F$2) -> 1 | G1295: =SUMIFS('DATA UPDATE'!$L:$L,'DATA UPDATE'!$E:$E,A1295,'DATA UPDATE'!$B:$B,$G$2) -> 0 | H1295: =SUMIFS('DATA UPDATE'!$L:$L,'DATA UPDATE'!$E:$E,A1295,'DATA UPDATE'!$B:$B,$H$2) -> 0 | I1295: =SUM(C1295:H1295) -> 1 | J1295: =SUMIFS('UPDATE STOCK'!F:F,'UPDATE STOCK'!A:A,วิเคราะห์ข้อมูล!A1295) -> 0 | K1295: =MAX(C1295:G1295) -> 1 | L1295: =MIN(C1295:G1295) -> 0 | M1295: =AVERAGE(C1295:G1295) -> 0.2 | N1295: =M1295-J1295 -> 0.2 | O1295: =SUMIFS('DATA UPDATE'!$L:$L,'DATA UPDATE'!$E:$E,วิเคราะห์ข้อมูล!A1295,'DATA UPDATE'!$T:$T,วิเคราะห์ข้อมูล!$O$2) -> 1 | P1295: =SUMIFS('DATA UPDATE'!$L:$L,'DATA UPDATE'!$E:$E,วิเคราะห์ข้อมูล!A1295,'DATA UPDATE'!$T:$T,วิเคราะห์ข้อมูล!$P$2) -> 0 | Q1295: =SUMIFS('DATA UPDATE'!$L:$L,'DATA UPDATE'!$E:$E,วิเคราะห์ข้อมูล!A1295,'DATA UPDATE'!$T:$T,วิเคราะห์ข้อมูล!$Q$2) -> 0 | R1295: =SUMIFS('DATA UPDATE'!$L:$L,'DATA UPDATE'!$D:$D,วิเคราะห์ข้อมูล!A1295,'DATA UPDATE'!$T:$T,วิเคราะห์ข้อมูล!$R$2) -> 0 | S1295: =SUMIFS('UPDATE STOCK'!$F:$F,'UPDATE STOCK'!$A:$A,A1295,'UPDATE STOCK'!$G:$G,$S$2) -> 0 | T1295: =SUMIFS('UPDATE STOCK'!$F:$F,'UPDATE STOCK'!$A:$A,A1295,'UPDATE STOCK'!$G:$G,$T$2) -> 0 | U1295: =SUMIFS('UPDATE STOCK'!$F:$F,'UPDATE STOCK'!$A:$A,วิเคราะห์ข้อมูล!A1295,'UPDATE STOCK'!$G:$G,$U$2) -> 0 | V1295: =SUMIFS('UPDATE STOCK'!$F:$F,'UPDATE STOCK'!$A:$A,วิเคราะห์ข้อมูล!A1295,'UPDATE STOCK'!$G:$G,$V$2) -> 0

Sheet รายการขายออกของแต่ละช่วง
A1: วันที่ | B1: (หลายรายการ)
A2: เดือน | B2: มิถุนายน
A4: ผลรวม ของ จำนวน | C4: สาขา
A5: รหัสสินค้า | B5: รายละเอียดสินค้า | C5: 340 | D5: บางใหญ่ | E5: บางบอน | F5: ราชพฤกษ | G5: ผลรวมทั้งหมด
A6: 001-A15 | B6: น้ำมัน Transmission off SUNOCO GL-5-140 เบอร์ 140 | C6: 4 | G6: 4
A7: 001-A24 | B7: *น้ำมันเกียร์ ซันโนโก้ ออยล์ GL5 80W-90 เบอร์90 | C7: 3 | G7: 3
A8: 001-A3 | B8: *น้ำมัน Castrol CRB Monograde ซุปเปอร์ดีเซลเบอร์40 | C8: 4 | G8: 4
A9: 001-A49 | B9: *น้ำมันเกียร์-4L-(CVT) Fiuid FE-ฝาดำ | D9: 1 | G9: 1
A10: 001-C3-6 | B10: *น้ำมัน Castrol CRB TURBO 15W40 CH4 (6 ลิตร ฟรี 1 ลิตร) | C10: 2 | G10: 2
A11: 001-PTT1-1 | B11: *น้ำมันเครื่อง PTT DYNAMIC COMMONRAL 10W30 6 ลิตร | D11: 1 | G11: 1
A12: 001-PTT1-2 | B12: *น้ำมันเครื่อง PTT DYNAMIC COMMONRAIL 10W30 1 ลิตร | D12: 1 | G12: 1
A13: 001-SUN1-15 | B13: *น้ำมันเคริ่อง SUNOCO 6 ลิตร 5W30 NAVATECH FULL SYN API CK4 | F13: 1 | G13: 1
A14: 001-ZIC2-1 | B14: *น้ำมันเครื่อง ZIC X7 FE 4 ลิตร 0W20 สีเทา FULLY SYNTHETIC | F14: 1 | G14: 1
A15: 001-ZIC-X51L | B15: *น้ำมันเครื่อง ZIC X5 DIESEL 1 ลิตร 10W30 สีน้ำเงิน CI-4/SJ | D15: 2 | E15: 2 | G15: 4
A16: 001-ZIC-X54L | B16: *น้ำมันเครื่อง ZIC X5 4 ลิตร 10W30 สีน้ำเงิน SK SYNTHETIC | D16: 3 | E16: 1 | G16: 4
A17: 001-ZIC-X56L | B17: *น้ำมันเครื่อง ZIC X5 DIESEL 6 ลิตร 10W30 สีน้ำเงิน CI-4/SJ | D17: 1 | E17: 1 | G17: 2
A18: 001-ZIC-X71LB | B18: *น้ำมันเครื่อง ZIC X7 SN 1 ลิตร 5W30 สีเทา SYNTHETIC | E18: 1 | G18: 1
A19: 001-ZIC-X74L | B19: *น้ำมันเครื่อง ZIC X7 SN 4 ลิตร 5W30 สีเทา SK SYNTHETIC | E19: 1 | G19: 1
A20: 003-2-3 | B20: *น้ำยาเติมหม้อน้ำและกันสนิม Castrol 1 L Radicool SF Premix | C20: 2 | G20: 2
A21: 003-2-4 | B21: *น้ำยาเติมหม้อน้ำและกันสนิม Castrol 4 L Radicool SF Premix | C21: 1 | G21: 1
A22: 004-F1-2 | B22: กรองเครื่อง M/Z BT50 PRO /FORD Ranger BB3Q (WLL7508) WIX | D22: 1 | G22: 1
A23: 004-H11-14 | B23: กรองเครื่องCOOL GEAR 260340-0700 H/D JAZZ^CITY^CIVIC DENSO | E23: 1 | F23: 1 | G23: 2
A24: 004-H11-4 | B24: *กรองเครื่อง VALUE 15400-PR3-505 H/D CIVIC^CITY ลูกเล็ก | D24: 1 | G24: 1
A25: 004-I5-29 | B25: *กรองเครื่อง COOL GEAR 260340-25804W I/S ALL-NEW D-MAX 1.9 | C25: 1 | D25: 1 | G25: 2
A26: 004-I5-3 | B26: *กรองเครื่อง VALUE I/S D-MAX 0524 BLUE POWER1.9-8-98270524-0 | E26: 1 | G26: 1
A27: 004-M1-8 | B27: *กรองเครื่อง 1230A186 TRITON 2.5 แท้ | C27: 1 | G27: 1
A28: 004-T2-12 | B28: *กรองเครื่อง DENSO T/Y VIGO^ CAMRY 260340-0520 | F28: 1 | G28: 1
A29: 004-T2-19 | B29: *กรองเครื่อง VALUE 90915-10001^YZZE1 T/Y โคโรล่า^แคมรี่^VIOS | E29: 1 | G29: 1
A30: 004-T2-33 | B30: *กรองเครื่อง COOL GEAR 260340-05004W T/Y VIOS^ CAMRY | D30: 2 | G30: 2
A31: 007-I5-18 | B31: *กรองอากาศ COOL-GEAR 260300-0651W I/S D-MAX ALL NEW 2.5 | C31: 1 | G31: 1
A32: 007-T2-31 | B32: *กรองอากาศ COOL GEAR 260300-01004W T/Y VIOS ^YARISปี 08-12 | D32: 1 | G32: 1
A33: 025-KP-410K02 | B33: *โช๊คอัพหน้า-ขวา T/Y VIGO 2 WD (341408) SKYB | D33: 1 | G33: 1
A34: 025-KP-420K02 | B34: *โช๊คอัพหน้า-ซ้าย T/Y VIGO 2 WD (341409) SKYB | D34: 1 | G34: 1
A35: 032-I5-2 | B35: *กรองฝุ่นแอร์ HRI 2502 I/S D-MAX ALL NEW ^CHEVROLET COLORADO | C35: 1 | G35: 1
A36: 032-T2-3 | B36: *กรองฝุ่นแอร์ HRT 2102 T/Y NEW ALTIS^NEW VIOS^NEW CAMRY | D36: 1 | G36: 1
A37: 036-T2-5 | B37: *ก้ามเบรคหลัง SNB-282 T/Y HI-LUX VIGO 2WD 2004 | D37: 1 | G37: 1
A38: 076-T2-46 | B38: *ดิสเบรคหน้าคอมแพค DPM-690 T/Y VIGO 2WD 04-08^ INNOVA 06UP | E38: 1 | G38: 1
A39: 130-CFBC-6 | B39: ผลิตภัณฑ์ทำความสะอาดเบรกและชิ้นส่วนเบรก FORTRON | D39: 2 | E39: 2 | G39: 4
A40: 130-TFBF-5 | B40: น้ำมันเบรก ซุปเปอร์ DOT 4 FORTRON | D40: 4 | G40: 4
A41: 130-TFEF-3 | B41: ผลิตภัณฑ์ทำความสะอาดภายในเครื่องยนต์ FORTRON | D41: 2 | G41: 2
...

Sheet DATA UPDATE
A1: วันที่ | B1: เดือน | C1: ปี | D1: รหัสลูกค้า | E1: รหัสสินค้า | F1: รายละเอียดสินค้า | G1: รายละเอียด | H1: ยี่ห้อ | I1: INV ลูกค้า | J1: ชื่อลูกค้า | K1: ผู้แทนขาย | L1: จำนวน | M1: ราคาขาย | N1: ส่วนลดรวม | O1: ส่วนลดต่อเส้น | P1: มูลค่ารวม | Q1: ภาษี 7% | R1: มูลค่ารวมภาษี | S1: คลัง | T1: สาขา
A2: 01/01/2026 | B2: มกราคม | C2: 2026 | D2: CP-13647 | E2: DL1856015-EC300+ | F2: 185/60R15 84H EC300+ | G2: ยางเล็ก DL | H2: DUNLOP | I2: CS.6256901/001 | J2: คุณ ปณิธิ จันทรรอด | K2: C13 | L2: 4 | M2: 2700 | N2: 2700 | P2: 7570.09 | Q2: 529.91 | R2: 8100 | S2: CP02Y25-M11 | T2: {=_xlfn.IFS(ISNUMBER(SEARCH("CP02",S2)),"ราชพฤกษ",ISNUMBER(SEARCH("CP03",S2)),"บางใหญ่",ISNUMBER(SEARCH("CP04",S2)),"บางบอน",OR(ISNUMBER(SEARCH("CP",S2)),ISNUMBER(SEARCH("BTC",D2))),"340",TRUE,"")} -> ราชพฤกษ
A3: 01/01/2026 | B3: มกราคม | C3: 2026 | D3: CP-13647 | E3: J001 | F3: TR413 VALVE MASTER EPDM | G3: อะไหล่ยางเล็ก | H3: อะไหล่นอก | I3: CS.6256901/001 | J3: คุณ ปณิธิ จันทรรอด | K3: C13 | L3: 4 | M3: 60 | N3: 0 | P3: 0 | Q3: 0 | R3: 0 | S3: CP02A | T3: {=_xlfn.IFS(ISNUMBER(SEARCH("CP02",S3)),"ราชพฤกษ",ISNUMBER(SEARCH("CP03",S3)),"บางใหญ่",ISNUMBER(SEARCH("CP04",S3)),"บางบอน",OR(ISNUMBER(SEARCH("CP",S3)),ISNUMBER(SEARCH("BTC",D3))),"340",TRUE,"")} -> ราชพฤกษ
A4: 01/01/2026 | B4: มกราคม | C4: 2026 | D4: CP-13647 | E4: SY03-0005 | F4: ค่าบริการ ถ่วงล้อ ขนาดกระทะล้อต่ำกว่า 18" (ยางรถยนต์ทั่วไป) | G4: ค่าแรง-ยางเล็ก | H4: ไม่กำหนด | I4: CS.6256901/001 | J4: คุณ ปณิธิ จันทรรอด | K4: C13 | L4: 4 | M4: 120 | N4: 0 | P4: 0 | Q4: 0 | R4: 0 | S4: CP02N | T4: {=_xlfn.IFS(ISNUMBER(SEARCH("CP02",S4)),"ราชพฤกษ",ISNUMBER(SEARCH("CP03",S4)),"บางใหญ่",ISNUMBER(SEARCH("CP04",S4)),"บางบอน",OR(ISNUMBER(SEARCH("CP",S4)),ISNUMBER(SEARCH("BTC",D4))),"340",TRUE,"")} -> ราชพฤกษ
A5: 01/01/2026 | B5: มกราคม | C5: 2026 | D5: CP-13647 | E5: SA01-00001 | F5: ค่าบริการ ตั้งศูนย์ล้อ ขนาดกระทะล้อต่ำกว่า 18" | G5: ค่าบริการตั้งศูนย์-ยางเล็ก | H5: ไม่กำหนด | I5: CS.6256901/001 | J5: คุณ ปณิธิ จันทรรอด | K5: C13 | L5: 1 | M5: 400 | N5: 0 | P5: 0 | Q5: 0 | R5: 0 | S5: CP02N | T5: {=_xlfn.IFS(ISNUMBER(SEARCH("CP02",S5)),"ราชพฤกษ",ISNUMBER(SEARCH("CP03",S5)),"บางใหญ่",ISNUMBER(SEARCH("CP04",S5)),"บางบอน",OR(ISNUMBER(SEARCH("CP",S5)),ISNUMBER(SEARCH("BTC",D5))),"340",TRUE,"")} -> ราชพฤกษ
A6: 01/01/2026 | B6: มกราคม | C6: 2026 | D6: CP-13647 | E6: G01-DL001 | F6: แก้วน้ำ DUNLOP | G6: ของแจกของแถม | H6: DUNLOP | I6: CS.6256901/001 | J6: คุณ ปณิธิ จันทรรอด | K6: C13 | L6: 2 | M6: 1 | N6: 0 | P6: 0 | Q6: 0 | R6: 0 | S6: CP02N | T6: {=_xlfn.IFS(ISNUMBER(SEARCH("CP02",S6)),"ราชพฤกษ",ISNUMBER(SEARCH("CP03",S6)),"บางใหญ่",ISNUMBER(SEARCH("CP04",S6)),"บางบอน",OR(ISNUMBER(SEARCH("CP",S6)),ISNUMBER(SEARCH("BTC",D6))),"340",TRUE,"")} -> ราชพฤกษ
A7: 01/01/2026 | B7: มกราคม | C7: 2026 | D7: CP-18206 | E7: DL2157015-LT37 | F7: 215/70R15C 109/107S SPLT37 | G7: ยางเล็ก DL | H7: DUNLOP | I7: CS.6256901/002 | J7: คุณอำนาจ ทิพวงษ์ | K7: C13 | L7: 4 | M7: 3160 | N7: 3160 | P7: 8859.81 | Q7: 620.19 | R7: 9480 | S7: CP02Y25-M08 | T7: {=_xlfn.IFS(ISNUMBER(SEARCH("CP02",S7)),"ราชพฤกษ",ISNUMBER(SEARCH("CP03",S7)),"บางใหญ่",ISNUMBER(SEARCH("CP04",S7)),"บางบอน",OR(ISNUMBER(SEARCH("CP",S7)),ISNUMBER(SEARCH("BTC",D7))),"340",TRUE,"")} -> ราชพฤกษ
A8: 01/01/2026 | B8: มกราคม | C8: 2026 | D8: CP-18206 | E8: J001 | F8: TR413 VALVE MASTER EPDM | G8: อะไหล่ยางเล็ก | H8: อะไหล่นอก | I8: CS.6256901/002 | J8: คุณอำนาจ ทิพวงษ์ | K8: C13 | L8: 4 | M8: 60 | N8: 0 | P8: 0 | Q8: 0 | R8: 0 | S8: CP02A | T8: {=_xlfn.IFS(ISNUMBER(SEARCH("CP02",S8)),"ราชพฤกษ",ISNUMBER(SEARCH("CP03",S8)),"บางใหญ่",ISNUMBER(SEARCH("CP04",S8)),"บางบอน",OR(ISNUMBER(SEARCH("CP",S8)),ISNUMBER(SEARCH("BTC",D8))),"340",TRUE,"")} -> ราชพฤกษ
A9: 01/01/2026 | B9: มกราคม | C9: 2026 | D9: CP-18206 | E9: SY03-0005 | F9: ค่าบริการ ถ่วงล้อ ขนาดกระทะล้อต่ำกว่า 18" (ยางรถยนต์ทั่วไป) | G9: ค่าแรง-ยางเล็ก | H9: ไม่กำหนด | I9: CS.6256901/002 | J9: คุณอำนาจ ทิพวงษ์ | K9: C13 | L9: 4 | M9: 120 | N9: 0 | P9: 0 | Q9: 0 | R9: 0 | S9: CP02N | T9: {=_xlfn.IFS(ISNUMBER(SEARCH("CP02",S9)),"ราชพฤกษ",ISNUMBER(SEARCH("CP03",S9)),"บางใหญ่",ISNUMBER(SEARCH("CP04",S9)),"บางบอน",OR(ISNUMBER(SEARCH("CP",S9)),ISNUMBER(SEARCH("BTC",D9))),"340",TRUE,"")} -> ราชพฤกษ
A10: 01/01/2026 | B10: มกราคม | C10: 2026 | D10: CP-18206 | E10: SA01-00001 | F10: ค่าบริการ ตั้งศูนย์ล้อ ขนาดกระทะล้อต่ำกว่า 18" | G10: ค่าบริการตั้งศูนย์-ยางเล็ก | H10: ไม่กำหนด | I10: CS.6256901/002 | J10: คุณอำนาจ ทิพวงษ์ | K10: C13 | L10: 1 | M10: 400 | N10: 0 | P10: 0 | Q10: 0 | R10: 0 | S10: CP02N | T10: {=_xlfn.IFS(ISNUMBER(SEARCH("CP02",S10)),"ราชพฤกษ",ISNUMBER(SEARCH("CP03",S10)),"บางใหญ่",ISNUMBER(SEARCH("CP04",S10)),"บางบอน",OR(ISNUMBER(SEARCH("CP",S10)),ISNUMBER(SEARCH("BTC",D10))),"340",TRUE,"")} -> ราชพฤกษ
A11: 01/01/2026 | B11: มกราคม | C11: 2026 | D11: CP-18206 | E11: B01-DL001 | F11: กระเป๋าเก็บความเย็น DUNLOP | G11: ของแจกของแถม | H11: DUNLOP | I11: CS.6256901/002 | J11: คุณอำนาจ ทิพวงษ์ | K11: C13 | L11: 1 | M11: 1 | N11: 0 | P11: 0 | Q11: 0 | R11: 0 | S11: CP02N | T11: {=_xlfn.IFS(ISNUMBER(SEARCH("CP02",S11)),"ราชพฤกษ",ISNUMBER(SEARCH("CP03",S11)),"บางใหญ่",ISNUMBER(SEARCH("CP04",S11)),"บางบอน",OR(ISNUMBER(SEARCH("CP",S11)),ISNUMBER(SEARCH("BTC",D11))),"340",TRUE,"")} -> ราชพฤกษ
A12: 01/01/2026 | B12: มกราคม | C12: 2026 | D12: CP-18208 | E12: BS2155517-T6 | F12: 215/55R17 94W BS TURANZA 6 | G12: ยางเล็ก BS | H12: BSยางเล็ก | I12: CS.6256901/003 | J12: คุณมงคล พฤกษอรุณ | K12: C13 | L12: 1 | M12: 5990 | N12: 0 | P12: 5598.13 | Q12: 391.87 | R12: 5990 | S12: CP02Y25-M10 | T12: {=_xlfn.IFS(ISNUMBER(SEARCH("CP02",S12)),"ราชพฤกษ",ISNUMBER(SEARCH("CP03",S12)),"บางใหญ่",ISNUMBER(SEARCH("CP04",S12)),"บางบอน",OR(ISNUMBER(SEARCH("CP",S12)),ISNUMBER(SEARCH("BTC",D12))),"340",TRUE,"")} -> ราชพฤกษ
A13: 01/01/2026 | B13: มกราคม | C13: 2026 | D13: CP-12717 | E13: DL1856015-EC300+ | F13: 185/60R15 84H EC300+ | G13: ยางเล็ก DL | H13: DUNLOP | I13: CS.8256901/001 | J13: คุณ พิกรม อโศกบุญรัตน์ | K13: C10 | L13: 4 | M13: 2700 | N13: 2700 | P13: 7570.09 | Q13: 529.91 | R13: 8100 | S13: CP03Y25-M11 | T13: {=_xlfn.IFS(ISNUMBER(SEARCH("CP02",S13)),"ราชพฤกษ",ISNUMBER(SEARCH("CP03",S13)),"บางใหญ่",ISNUMBER(SEARCH("CP04",S13)),"บางบอน",OR(ISNUMBER(SEARCH("CP",S13)),ISNUMBER(SEARCH("BTC",D13))),"340",TRUE,"")} -> บางใหญ่
... A8468: 15/05/2026 | B8468: พฤษภาคม | C8468: 2026 | D8468: CP-09010 | E8468: A096-H11-44 | F8468: กันกระแทกหน้า HONDA FREED 08-16 | G8468: อะไหล่นอก ยางเล็ก | H8468: ไม่กำหนด | I8468: CS.2256905/027 | J8468: บริษัท สิงค์-ไทย รีไซเคิล จำกัด | K8468: BB/พงษ์ | L8468: 2 | M8468: 260 | N8468: 0 | P8468: 485.98 | Q8468: 34.02 | R8468: 520 | S8468: CP04A | T8468: {=_xlfn.IFS(ISNUMBER(SEARCH("CP02",S8468)),"ราชพฤกษ",ISNUMBER(SEARCH("CP03",S8468)),"บางใหญ่",ISNUMBER(SEARCH("CP04",S8468)),"บางบอน",OR(ISNUMBER(SEARCH("CP",S8468)),ISNUMBER(SEARCH("BTC",D8468))),"340",TRUE,"")} -> บางบอน
A8469: 15/05/2026 | B8469: พฤษภาคม | C8469: 2026 | D8469: BTC-0000339 | E8469: 9002 | F8469: จำนวนรถเข้า | G8469: อะไหล่sac | H8469: ไม่กำหนด | I8469: CS.2256905/028 | J8469: บริษัท เมอร์เมดโลจิสติกส์ จำกัด | K8469: B1 | L8469: 1 | M8469: 1 | N8469: 1 | P8469: 0 | Q8469: 0 | R8469: 0 | S8469: BTCN | T8469: {=_xlfn.IFS(ISNUMBER(SEARCH("CP02",S8469)),"ราชพฤกษ",ISNUMBER(SEARCH("CP03",S8469)),"บางใหญ่",ISNUMBER(SEARCH("CP04",S8469)),"บางบอน",OR(ISNUMBER(SEARCH("CP",S8469)),ISNUMBER(SEARCH("BTC",D8469))),"340",TRUE,"")} -> 340
A8470: 15/05/2026 | B8470: พฤษภาคม | C8470: 2026 | D8470: BTC-0000339 | E8470: LL1122518-KTT307 | F8470: 11R22.5 18PR KTT307 149/146K LL TIS | G8470: ยางใหญ่ LL TBR/LTR (ยางใหญ่) | H8470: LINGLONG ยางใหญ่ | I8470: CS.2256905/028 | J8470: บริษัท เมอร์เมดโลจิสติกส์ จำกัด | K8470: B1 | L8470: 1 | M8470: 5200 | N8470: 0 | P8470: 4859.81 | Q8470: 340.19 | R8470: 5200 | S8470: BTCY26-M04 | T8470: {=_xlfn.IFS(ISNUMBER(SEARCH("CP02",S8470)),"ราชพฤกษ",ISNUMBER(SEARCH("CP03",S8470)),"บางใหญ่",ISNUMBER(SEARCH("CP04",S8470)),"บางบอน",OR(ISNUMBER(SEARCH("CP",S8470)),ISNUMBER(SEARCH("BTC",D8470))),"340",TRUE,"")} -> 340
